Workbook

Sheet グラフ
B5: 22年労働力調査_基本集計全都道府県全国年次
A6: 実数 | F6: 全体 | M6: 男女別
B7: 産業 | C7: 就業者全体 | E7: 万人 | J7: 単位：万人 | Q7: 単位：万人
C8: 全体 | D8: 男性 | E8: 女性
B9: 15～19歳 | C9: =_xlfn.XLOOKUP($C$7,'ローデータ＋比率'!$DK$10:$HE$10,'ローデータ＋比率'!O13:DI13,"") -> 106 | D9: =_xlfn.XLOOKUP($C$7,'ローデータ＋比率'!$DK$10:$HE$10,'ローデータ＋比率'!O27:DI27,"") -> 51 | E9: =_xlfn.XLOOKUP($C$7,'ローデータ＋比率'!$DK$10:$HE$10,'ローデータ＋比率'!O40:DI40,"") -> 55
B10: 20～24歳 | C10: =_xlfn.XLOOKUP($C$7,'ローデータ＋比率'!$DK$10:$HE$10,'ローデータ＋比率'!O14:DI14,"") -> 441 | D10: =_xlfn.XLOOKUP($C$7,'ローデータ＋比率'!$DK$10:$HE$10,'ローデータ＋比率'!O28:DI28,"") -> 222 | E10: =_xlfn.XLOOKUP($C$7,'ローデータ＋比率'!$DK$10:$HE$10,'ローデータ＋比率'!O41:DI41,"") -> 219
B11: 25～29歳 | C11: =_xlfn.XLOOKUP($C$7,'ローデータ＋比率'!$DK$10:$HE$10,'ローデータ＋比率'!O15:DI15,"") -> 558 | D11: =_xlfn.XLOOKUP($C$7,'ローデータ＋比率'!$DK$10:$HE$10,'ローデータ＋比率'!O29:DI29,"") -> 295 | E11: =_xlfn.XLOOKUP($C$7,'ローデータ＋比率'!$DK$10:$HE$10,'ローデータ＋比率'!O42:DI42,"") -> 263
B12: 30～34歳 | C12: =_xlfn.XLOOKUP($C$7,'ローデータ＋比率'!$DK$10:$HE$10,'ローデータ＋比率'!O16:DI16,"") -> 552 | D12: =_xlfn.XLOOKUP($C$7,'ローデータ＋比率'!$DK$10:$HE$10,'ローデータ＋比率'!O30:DI30,"") -> 305 | E12: =_xlfn.XLOOKUP($C$7,'ローデータ＋比率'!$DK$10:$HE$10,'ローデータ＋比率'!O43:DI43,"") -> 247
B13: 35～39歳 | C13: =_xlfn.XLOOKUP($C$7,'ローデータ＋比率'!$DK$10:$HE$10,'ローデータ＋比率'!O17:DI17,"") -> 619 | D13: =_xlfn.XLOOKUP($C$7,'ローデータ＋比率'!$DK$10:$HE$10,'ローデータ＋比率'!O31:DI31,"") -> 345 | E13: =_xlfn.XLOOKUP($C$7,'ローデータ＋比率'!$DK$10:$HE$10,'ローデータ＋比率'!O44:DI44,"") -> 274
B14: 40～44歳 | C14: =_xlfn.XLOOKUP($C$7,'ローデータ＋比率'!$DK$10:$HE$10,'ローデータ＋比率'!O18:DI18,"") -> 694 | D14: =_xlfn.XLOOKUP($C$7,'ローデータ＋比率'!$DK$10:$HE$10,'ローデータ＋比率'!O32:DI32,"") -> 380 | E14: =_xlfn.XLOOKUP($C$7,'ローデータ＋比率'!$DK$10:$HE$10,'ローデータ＋比率'!O45:DI45,"") -> 314
B15: 45～49歳 | C15: =_xlfn.XLOOKUP($C$7,'ローデータ＋比率'!$DK$10:$HE$10,'ローデータ＋比率'!O19:DI19,"") -> 830 | D15: =_xlfn.XLOOKUP($C$7,'ローデータ＋比率'!$DK$10:$HE$10,'ローデータ＋比率'!O33:DI33,"") -> 452 | E15: =_xlfn.XLOOKUP($C$7,'ローデータ＋比率'!$DK$10:$HE$10,'ローデータ＋比率'!O46:DI46,"") -> 378
B16: 50～54歳 | C16: =_xlfn.XLOOKUP($C$7,'ローデータ＋比率'!$DK$10:$HE$10,'ローデータ＋比率'!O20:DI20,"") -> 806 | D16: =_xlfn.XLOOKUP($C$7,'ローデータ＋比率'!$DK$10:$HE$10,'ローデータ＋比率'!O34:DI34,"") -> 438 | E16: =_xlfn.XLOOKUP($C$7,'ローデータ＋比率'!$DK$10:$HE$10,'ローデータ＋比率'!O47:DI47,"") -> 369
B17: 55～59歳 | C17: =_xlfn.XLOOKUP($C$7,'ローデータ＋比率'!$DK$10:$HE$10,'ローデータ＋比率'!O21:DI21,"") -> 662 | D17: =_xlfn.XLOOKUP($C$7,'ローデータ＋比率'!$DK$10:$HE$10,'ローデータ＋比率'!O35:DI35,"") -> 365 | E17: =_xlfn.XLOOKUP($C$7,'ローデータ＋比率'!$DK$10:$HE$10,'ローデータ＋比率'!O48:DI48,"") -> 296
B18: 60～64歳 | C18: =_xlfn.XLOOKUP($C$7,'ローデータ＋比率'!$DK$10:$HE$10,'ローデータ＋比率'!O22:DI22,"") -> 542 | D18: =_xlfn.XLOOKUP($C$7,'ローデータ＋比率'!$DK$10:$HE$10,'ローデータ＋比率'!O36:DI36,"") -> 308 | E18: =_xlfn.XLOOKUP($C$7,'ローデータ＋比率'!$DK$10:$HE$10,'ローデータ＋比率'!O49:DI49,"") -> 235
B19: 65歳以上 | C19: =_xlfn.XLOOKUP($C$7,'ローデータ＋比率'!$DK$10:$HE$10,'ローデータ＋比率'!O23:DI23,"") -> 912 | D19: =_xlfn.XLOOKUP($C$7,'ローデータ＋比率'!$DK$10:$HE$10,'ローデータ＋比率'!O37:DI37,"") -> 538 | E19: =_xlfn.XLOOKUP($C$7,'ローデータ＋比率'!$DK$10:$HE$10,'ローデータ＋比率'!O50:DI50,"") -> 375
B20: 15～64歳 | C20: =_xlfn.XLOOKUP($C$7,'ローデータ＋比率'!$DK$10:$HE$10,'ローデータ＋比率'!O24:DI24,"") -> 5810 | D20: =_xlfn.XLOOKUP($C$7,'ローデータ＋比率'!$DK$10:$HE$10,'ローデータ＋比率'!O26:DI26,"") -> 3161 | E20: =_xlfn.XLOOKUP($C$7,'ローデータ＋比率'!$DK$10:$HE$10,'ローデータ＋比率'!O39:DI39,"") -> 2649
C21: =SUM(C9:C19) -> 6722 | D21: =SUM(D9:D19) -> 3699 | E21: =SUM(E9:E19) -> 3025
A36: 比率 | F36: 全体 | M36: 男女別
C38: 全体 | D38: 男性 | E38: 女性
B39: 15～19歳 | C39: =_xlfn.XLOOKUP($C$7,'ローデータ＋比率'!$DK$10:$HE$10,'ローデータ＋比率'!$DK13:$HE13,"") -> 0.015766771 | D39: =_xlfn.XLOOKUP($C$7,'ローデータ＋比率'!$DK$10:$HE$10,'ローデータ＋比率'!$DK27:$HE27,"") -> 0.01378751 | E39: =_xlfn.XLOOKUP($C$7,'ローデータ＋比率'!$DK$10:$HE$10,'ローデータ＋比率'!$DK40:$HE40,"") -> 0.018187831
B40: 20～24歳 | C40: =_xlfn.XLOOKUP($C$7,'ローデータ＋比率'!$DK$10:$HE$10,'ローデータ＋比率'!$DK14:$HE14,"") -> 0.065595716 | D40: =_xlfn.XLOOKUP($C$7,'ローデータ＋比率'!$DK$10:$HE$10,'ローデータ＋比率'!$DK28:$HE28,"") -> 0.060016221 | E40: =_xlfn.XLOOKUP($C$7,'ローデータ＋比率'!$DK$10:$HE$10,'ローデータ＋比率'!$DK41:$HE41,"") -> 0.072420635
B41: 25～29歳 | C41: =_xlfn.XLOOKUP($C$7,'ローデータ＋比率'!$DK$10:$HE$10,'ローデータ＋比率'!$DK15:$HE15,"") -> 0.082998661 | D41: =_xlfn.XLOOKUP($C$7,'ローデータ＋比率'!$DK$10:$HE$10,'ローデータ＋比率'!$DK29:$HE29,"") -> 0.079751284 | E41: =_xlfn.XLOOKUP($C$7,'ローデータ＋比率'!$DK$10:$HE$10,'ローデータ＋比率'!$DK42:$HE42,"") -> 0.086970899
B42: 30～34歳 | C42: =_xlfn.XLOOKUP($C$7,'ローデータ＋比率'!$DK$10:$HE$10,'ローデータ＋比率'!$DK16:$HE16,"") -> 0.082106203 | D42: =_xlfn.XLOOKUP($C$7,'ローデータ＋比率'!$DK$10:$HE$10,'ローデータ＋比率'!$DK30:$HE30,"") -> 0.082454717 | E42: =_xlfn.XLOOKUP($C$7,'ローデータ＋比率'!$DK$10:$HE$10,'ローデータ＋比率'!$DK43:$HE43,"") -> 0.081679894
B43: 35～39歳 | C43: =_xlfn.XLOOKUP($C$7,'ローデータ＋比率'!$DK$10:$HE$10,'ローデータ＋比率'!$DK17:$HE17,"") -> 0.092071992 | D43: =_xlfn.XLOOKUP($C$7,'ローデータ＋比率'!$DK$10:$HE$10,'ローデータ＋比率'!$DK31:$HE31,"") -> 0.093268451 | E43: =_xlfn.XLOOKUP($C$7,'ローデータ＋比率'!$DK$10:$HE$10,'ローデータ＋比率'!$DK44:$HE44,"") -> 0.090608466
B44: 40～44歳 | C44: =_xlfn.XLOOKUP($C$7,'ローデータ＋比率'!$DK$10:$HE$10,'ローデータ＋比率'!$DK18:$HE18,"") -> 0.10322773 | D44: =_xlfn.XLOOKUP($C$7,'ローデータ＋比率'!$DK$10:$HE$10,'ローデータ＋比率'!$DK32:$HE32,"") -> 0.10273047 | E44: =_xlfn.XLOOKUP($C$7,'ローデータ＋比率'!$DK$10:$HE$10,'ローデータ＋比率'!$DK45:$HE45,"") -> 0.10383598
B45: 45～49歳 | C45: =_xlfn.XLOOKUP($C$7,'ローデータ＋比率'!$DK$10:$HE$10,'ローデータ＋比率'!$DK19:$HE19,"") -> 0.12345679 | D45: =_xlfn.XLOOKUP($C$7,'ローデータ＋比率'!$DK$10:$HE$10,'ローデータ＋比率'!$DK33:$HE33,"") -> 0.12219519 | E45: =_xlfn.XLOOKUP($C$7,'ローデータ＋比率'!$DK$10:$HE$10,'ローデータ＋比率'!$DK46:$HE46,"") -> 0.125
B46: 50～54歳 | C46: =_xlfn.XLOOKUP($C$7,'ローデータ＋比率'!$DK$10:$HE$10,'ローデータ＋比率'!$DK20:$HE20,"") -> 0.11988696 | D46: =_xlfn.XLOOKUP($C$7,'ローデータ＋比率'!$DK$10:$HE$10,'ローデータ＋比率'!$DK34:$HE34,"") -> 0.11841038 | E46: =_xlfn.XLOOKUP($C$7,'ローデータ＋比率'!$DK$10:$HE$10,'ローデータ＋比率'!$DK47:$HE47,"") -> 0.12202381
B47: 55～59歳 | C47: =_xlfn.XLOOKUP($C$7,'ローデータ＋比率'!$DK$10:$HE$10,'ローデータ＋比率'!$DK21:$HE21,"") -> 0.098467946 | D47: =_xlfn.XLOOKUP($C$7,'ローデータ＋比率'!$DK$10:$HE$10,'ローデータ＋比率'!$DK35:$HE35,"") -> 0.098675318 | E47: =_xlfn.XLOOKUP($C$7,'ローデータ＋比率'!$DK$10:$HE$10,'ローデータ＋比率'!$DK48:$HE48,"") -> 0.097883598
B48: 60～64歳 | C48: =_xlfn.XLOOKUP($C$7,'ローデータ＋比率'!$DK$10:$HE$10,'ローデータ＋比率'!$DK22:$HE22,"") -> 0.080618771 | D48: =_xlfn.XLOOKUP($C$7,'ローデータ＋比率'!$DK$10:$HE$10,'ローデータ＋比率'!$DK36:$HE36,"") -> 0.083265747 | E48: =_xlfn.XLOOKUP($C$7,'ローデータ＋比率'!$DK$10:$HE$10,'ローデータ＋比率'!$DK49:$HE49,"") -> 0.07771164
B49: 65歳以上 | C49: =_xlfn.XLOOKUP($C$7,'ローデータ＋比率'!$DK$10:$HE$10,'ローデータ＋比率'!$DK23:$HE23,"") -> 0.13565373 | D49: =_xlfn.XLOOKUP($C$7,'ローデータ＋比率'!$DK$10:$HE$10,'ローデータ＋比率'!$DK37:$HE37,"") -> 0.14544471 | E49: =_xlfn.XLOOKUP($C$7,'ローデータ＋比率'!$DK$10:$HE$10,'ローデータ＋比率'!$DK50:$HE50,"") -> 0.12400794
B50: 15～64歳 | C50: =_xlfn.XLOOKUP($C$7,'ローデータ＋比率'!$DK$10:$HE$10,'ローデータ＋比率'!$DK24:$HE24,"") -> 0.86419753 | D50: =_xlfn.XLOOKUP($C$7,'ローデータ＋比率'!$DK$10:$HE$10,'ローデータ＋比率'!$DK26:$HE26,"") -> 0.85455529 | E50: =_xlfn.XLOOKUP($C$7,'ローデータ＋比率'!$DK$10:$HE$10,'ローデータ＋比率'!$DK39:$HE39,"") -> 0.87599206
C51: =SUM(C39:C49) -> 0.99985126 | D51: =SUM(D39:D49) -> 1 | E51: =SUM(E39:E49) -> 1.0003307

Sheet データベース
A1: 性別 | B1: 年齢 | C1: 産業 | D1: 人数_万人
A2: 男女計 | B2: 全年齢 | C2: 全体 | D2: 6723
A3: 男女計 | B3: 全年齢 | C3: 農業，林業 | D3: 192
A4: 男女計 | B4: 全年齢 | C4: 農業 | D4: 185
A5: 男女計 | B5: 全年齢 | C5: 林業 | D5: 7
A6: 男女計 | B6: 全年齢 | C6: 非農林業 | D6: 6531
A7: 男女計 | B7: 全年齢 | C7: 漁業 | D7: 13
A8: 男女計 | B8: 全年齢 | C8: 漁業(水産養殖業を除く) | D8: 9
A9: 男女計 | B9: 全年齢 | C9: 水産養殖業 | D9: 4
A10: 男女計 | B10: 全年齢 | C10: 鉱業，採石業，砂利採取業 | D10: 2
A11: 男女計 | B11: 全年齢 | C11: 建設業 | D11: 479
A12: 男女計 | B12: 全年齢 | C12: 製造業 | D12: 1044
A13: 男女計 | B13: 全年齢 | C13: 食料品製造業 | D13: 133
... A202: 男女計 | B202: 15～19歳 | C202: 農業 | D202: 1
A203: 男女計 | B203: 15～19歳 | C203: 林業 | D203: -
A204: 男女計 | B204: 15～19歳 | C204: 非農林業 | D204: 105
A205: 男女計 | B205: 15～19歳 | C205: 漁業 | D205: 0
A206: 男女計 | B206: 15～19歳 | C206: 漁業(水産養殖業を除く) | D206: 0
A207: 男女計 | B207: 15～19歳 | C207: 水産養殖業 | D207: -
A208: 男女計 | B208: 15～19歳 | C208: 鉱業，採石業，砂利採取業 | D208: -
A209: 男女計 | B209: 15～19歳 | C209: 建設業 | D209: 3
A210: 男女計 | B210: 15～19歳 | C210: 製造業 | D210: 10
A211: 男女計 | B211: 15～19歳 | C211: 食料品製造業 | D211: 2
A212: 男女計 | B212: 15～19歳 | C212: 飲料・たばこ・飼料製造業 | D212: 0
A213: 男女計 | B213: 15～19歳 | C213: 繊維工業 | D213: 0
A214: 男女計 | B214: 15～19歳 | C214: 木材・木製品製造業(家具を除く) | D214: 0
A215: 男女計 | B215: 15～19歳 | C215: 家具・装備品製造業 | D215: 0
A216: 男女計 | B216: 15～19歳 | C216: パルプ・紙・紙加工品製造業 | D216: 0
A217: 男女計 | B217: 15～19歳 | C217: 印刷・同関連業 | D217: 0
A218: 男女計 | B218: 15～19歳 | C218: 化学工業 | D218: 1
A219: 男女計 | B219: 15～19歳 | C219: 石油製品・石炭製品製造業 | D219: 0
A220: 男女計 | B220: 15～19歳 | C220: プラスチック製品製造業(別掲を除く) | D220: 0
... A246: 男女計 | B246: 15～19歳 | C246: 水運業 | D246: 0
A247: 男女計 | B247: 15～19歳 | C247: 航空運輸業 | D247: -
A248: 男女計 | B248: 15～19歳 | C248: 倉庫業 | D248: 0
A249: 男女計 | B249: 15～19歳 | C249: 運輸に附帯するサービス業 | D249: 0
A250: 男女計 | B250: 15～19歳 | C250: 郵便業(信書便事業を含む) | D250: 0
A251: 男女計 | B251: 15～19歳 | C251: 卸売業，小売業 | D251: 30
A252: 男女計 | B252: 15～19歳 | C252: 卸売業 | D252: 1
A253: 男女計 | B253: 15～19歳 | C253: 各種商品小売業 | D253: 1
...

Sheet 男女合計
A1: 項目 | B1: 属性 | C1: 値
A2: 男女計 | B2: 全体 | C2: 6723
A3: 男女計 | B3: 農業，林業 | C3: 192
A4: 男女計 | B4: 農業 | C4: 185
A5: 男女計 | B5: 林業 | C5: 7
A6: 男女計 | B6: 非農林業 | C6: 6531
A7: 男女計 | B7: 漁業 | C7: 13
A8: 男女計 | B8: 漁業(水産養殖業を除く) | C8: 9
A9: 男女計 | B9: 水産養殖業 | C9: 4
A10: 男女計 | B10: 鉱業，採石業，砂利採取業 | C10: 2
A11: 男女計 | B11: 建設業 | C11: 479
A12: 男女計 | B12: 製造業 | C12: 1044
A13: 男女計 | B13: 食料品製造業 | C13: 133
... A202: 男女計_15～19歳 | B202: 農業 | C202: 1
A203: 男女計_15～19歳 | B203: 林業 | C203: -
A204: 男女計_15～19歳 | B204: 非農林業 | C204: 105
A205: 男女計_15～19歳 | B205: 漁業 | C205: 0
A206: 男女計_15～19歳 | B206: 漁業(水産養殖業を除く) | C206: 0
A207: 男女計_15～19歳 | B207: 水産養殖業 | C207: -
A208: 男女計_15～19歳 | B208: 鉱業，採石業，砂利採取業 | C208: -
A209: 男女計_15～19歳 | B209: 建設業 | C209: 3
A210: 男女計_15～19歳 | B210: 製造業 | C210: 10
A211: 男女計_15～19歳 | B211: 食料品製造業 | C211: 2
A212: 男女計_15～19歳 | B212: 飲料・たばこ・飼料製造業 | C212: 0
A213: 男女計_15～19歳 | B213: 繊維工業 | C213: 0
A214: 男女計_15～19歳 | B214: 木材・木製品製造業(家具を除く) | C214: 0
A215: 男女計_15～19歳 | B215: 家具・装備品製造業 | C215: 0
A216: 男女計_15～19歳 | B216: パルプ・紙・紙加工品製造業 | C216: 0
A217: 男女計_15～19歳 | B217: 印刷・同関連業 | C217: 0
A218: 男女計_15～19歳 | B218: 化学工業 | C218: 1
A219: 男女計_15～19歳 | B219: 石油製品・石炭製品製造業 | C219: 0
A220: 男女計_15～19歳 | B220: プラスチック製品製造業(別掲を除く) | C220: 0
... A246: 男女計_15～19歳 | B246: 水運業 | C246: 0
A247: 男女計_15～19歳 | B247: 航空運輸業 | C247: -
A248: 男女計_15～19歳 | B248: 倉庫業 | C248: 0
A249: 男女計_15～19歳 | B249: 運輸に附帯するサービス業 | C249: 0
A250: 男女計_15～19歳 | B250: 郵便業(信書便事業を含む) | C250: 0
A251: 男女計_15～19歳 | B251: 卸売業，小売業 | C251: 30
A252: 男女計_15～19歳 | B252: 卸売業 | C252: 1
A253: 男女計_15～19歳 | B253: 各種商品小売業 | C253: 1
...

Sheet 男性 (2)
A1: 項目 | B1: 属性 | C1: 値
A2: 男性 | B2: 全体 | C2: 3699
A3: 男性 | B3: 農業，林業 | C3: 118
A4: 男性 | B4: 農業 | C4: 113
A5: 男性 | B5: 林業 | C5: 5
A6: 男性 | B6: 非農林業 | C6: 3580
A7: 男性 | B7: 漁業 | C7: 10
A8: 男性 | B8: 漁業(水産養殖業を除く) | C8: 8
A9: 男性 | B9: 水産養殖業 | C9: 3
A10: 男性 | B10: 鉱業，採石業，砂利採取業 | C10: 2
A11: 男性 | B11: 建設業 | C11: 394
A12: 男性 | B12: 製造業 | C12: 732
A13: 男性 | B13: 食料品製造業 | C13: 65
... A202: 男性_15～19歳 | B202: 農業 | C202: 0
A203: 男性_15～19歳 | B203: 林業 | C203: -
A204: 男性_15～19歳 | B204: 非農林業 | C204: 50
A205: 男性_15～19歳 | B205: 漁業 | C205: 0
A206: 男性_15～19歳 | B206: 漁業(水産養殖業を除く) | C206: 0
A207: 男性_15～19歳 | B207: 水産養殖業 | C207: -
A208: 男性_15～19歳 | B208: 鉱業，採石業，砂利採取業 | C208: -
A209: 男性_15～19歳 | B209: 建設業 | C209: 3
A210: 男性_15～19歳 | B210: 製造業 | C210: 6
A211: 男性_15～19歳 | B211: 食料品製造業 | C211: 1
A212: 男性_15～19歳 | B212: 飲料・たばこ・飼料製造業 | C212: 0
A213: 男性_15～19歳 | B213: 繊維工業 | C213: 0
A214: 男性_15～19歳 | B214: 木材・木製品製造業(家具を除く) | C214: 0
A215: 男性_15～19歳 | B215: 家具・装備品製造業 | C215: 0
A216: 男性_15～19歳 | B216: パルプ・紙・紙加工品製造業 | C216: 0
A217: 男性_15～19歳 | B217: 印刷・同関連業 | C217: 0
A218: 男性_15～19歳 | B218: 化学工業 | C218: 1
A219: 男性_15～19歳 | B219: 石油製品・石炭製品製造業 | C219: 0
A220: 男性_15～19歳 | B220: プラスチック製品製造業(別掲を除く) | C220: 0
A221: 男性_15～19歳 | B221: ゴム製品製造業 | C221: 0
A222: 男性_15～19歳 | B222: なめし革・同製品・毛皮製造業 | C222: -
A223: 男性_15～19歳 | B223: 窯業・土石製品製造業 | C223: 0
A224: 男性_15～19歳 | B224: 鉄鋼業 | C224: 0
A225: 男性_15～19歳 | B225: 非鉄金属製造業 | C225: 0
A226: 男性_15～19歳 | B226: 金属製品製造業 | C226: 1
A227: 男性_15～19歳 | B227: はん用機械器具製造業 | C227: 0
A228: 男性_15～19歳 | B228: 生産用機械器具製造業 | C228: 0
...

Sheet 女性 (2)
A1: 項目 | B1: 属性 | C1: 値
A2: 女性 | B2: 全体 | C2: 3024
A3: 女性 | B3: 農業，林業 | C3: 74
A4: 女性 | B4: 農業 | C4: 73
A5: 女性 | B5: 林業 | C5: 1
A6: 女性 | B6: 非農林業 | C6: 2950
A7: 女性 | B7: 漁業 | C7: 2
A8: 女性 | B8: 漁業(水産養殖業を除く) | C8: 1
A9: 女性 | B9: 水産養殖業 | C9: 1
A10: 女性 | B10: 鉱業，採石業，砂利採取業 | C10: 0
A11: 女性 | B11: 建設業 | C11: 85
A12: 女性 | B12: 製造業 | C12: 312
A13: 女性 | B13: 食料品製造業 | C13: 68
... A202: 女性_15～19歳 | B202: 農業 | C202: 0
A203: 女性_15～19歳 | B203: 林業 | C203: -
A204: 女性_15～19歳 | B204: 非農林業 | C204: 55
A205: 女性_15～19歳 | B205: 漁業 | C205: -
A206: 女性_15～19歳 | B206: 漁業(水産養殖業を除く) | C206: -
A207: 女性_15～19歳 | B207: 水産養殖業 | C207: -
A208: 女性_15～19歳 | B208: 鉱業，採石業，砂利採取業 | C208: -
A209: 女性_15～19歳 | B209: 建設業 | C209: 0
A210: 女性_15～19歳 | B210: 製造業 | C210: 3
A211: 女性_15～19歳 | B211: 食料品製造業 | C211: 1
A212: 女性_15～19歳 | B212: 飲料・たばこ・飼料製造業 | C212: 0
A213: 女性_15～19歳 | B213: 繊維工業 | C213: 0
A214: 女性_15～19歳 | B214: 木材・木製品製造業(家具を除く) | C214: 0
A215: 女性_15～19歳 | B215: 家具・装備品製造業 | C215: 0
A216: 女性_15～19歳 | B216: パルプ・紙・紙加工品製造業 | C216: 0
A217: 女性_15～19歳 | B217: 印刷・同関連業 | C217: 0
A218: 女性_15～19歳 | B218: 化学工業 | C218: 0
A219: 女性_15～19歳 | B219: 石油製品・石炭製品製造業 | C219: -
A220: 女性_15～19歳 | B220: プラスチック製品製造業(別掲を除く) | C220: 0
A221: 女性_15～19歳 | B221: ゴム製品製造業 | C221: 0
A222: 女性_15～19歳 | B222: なめし革・同製品・毛皮製造業 | C222: 0
A223: 女性_15～19歳 | B223: 窯業・土石製品製造業 | C223: 0
A224: 女性_15～19歳 | B224: 鉄鋼業 | C224: 0
A225: 女性_15～19歳 | B225: 非鉄金属製造業 | C225: 0
A226: 女性_15～19歳 | B226: 金属製品製造業 | C226: 0
A227: 女性_15～19歳 | B227: はん用機械器具製造業 | C227: 0
A228: 女性_15～19歳 | B228: 生産用機械器具製造業 | C228: 0
...

Sheet 男女計
I1: 1 | J1: 2 | K1: 3 | L1: 4 | M1: 5 | N1: 6 | O1: 7 | P1: 8 | Q1: 9 | R1: 10 | S1: 11 | T1: 12 | U1: 13 | V1: 14 | W1: 15 | X1: 16 | Y1: 17 | Z1: 18 | AA1: 19 | AB1: 20 | AC1: 21 | AD1: 22 | AE1: 23 | AF1: 24 | AG1: 25 | AH1: 26 | AI1: 27 | AJ1: 28 | AK1: 29 | AL1: 30 | AM1: 31 | AN1: 32 | AO1: 33 | AP1: 34 | AQ1: 35 | AR1: 36 | AS1: 37 | AT1: 38 | AU1: 39 | AV1: 40 | AW1: 41 | AX1: 42 | AY1: 43 | AZ1: 44 | BA1: 45 | BB1: 46 | BC1: 47 | BD1: 48 | BE1: 49 | BF1: 50 | BG1: 51 | BH1: 52 | BI1: 53 | BJ1: 54 | BK1: 55 | BL1: 56 | BM1: 57 | BN1: 58 | BO1: 59 | BP1: 60 | BQ1: 61 | BR1: 62 | BS1: 63 | BT1: 64 | BU1: 65 | BV1: 66 | BW1: 67 | BX1: 68 | BY1: 69 | BZ1: 70 | CA1: 71 | CB1: 72 | CC1: 73 | CD1: 74 | CE1: 75 | CF1: 76 | CG1: 77 | CH1: 78 | CI1: 79 | CJ1: 80 | CK1: 81 | CL1: 82 | CM1: 83 | CN1: 84 | CO1: 85 | CP1: 86 | CQ1: 87 | CR1: 88 | CS1: 89 | CT1: 90 | CU1: 91 | CV1: 92 | CW1: 93 | CX1: 94 | CY1: 95 | CZ1: 96 | DA1: 97 | DB1: 98 | DC1: 99
I2: 1 | J2: 2 | K2: 3 | L2: 4 | M2: 5 | N2: 6 | O2: 7 | P2: 8 | Q2: 9 | R2: 10 | S2: 11 | T2: 12 | U2: 13 | V2: 14 | W2: 15 | X2: 16 | Y2: 17 | Z2: 18 | AA2: 19 | AB2: 20 | AC2: 21 | AD2: 22 | AE2: 23 | AF2: 24 | AG2: 25 | AH2: 26 | AI2: 27 | AJ2: 28 | AK2: 29 | AL2: 30 | AM2: 31 | AN2: 32 | AO2: 33 | AP2: 34 | AQ2: 35 | AR2: 36 | AS2: 37 | AT2: 38 | AU2: 39 | AV2: 40 | AW2: 41 | AX2: 42 | AY2: 43 | AZ2: 44 | BA2: 45 | BB2: 46 | BC2: 47 | BD2: 48 | BE2: 49 | BF2: 50 | BG2: 51 | BH2: 52 | BI2: 53 | BJ2: 54 | BK2: 55 | BL2: 56 | BM2: 57 | BN2: 58 | BO2: 59 | BP2: 60 | BQ2: 61 | BR2: 62 | BS2: 63 | BT2: 64 | BU2: 65 | BV2: 66 | BW2: 67 | BX2: 68 | BY2: 69 | BZ2: 70 | CA2: 71 | CB2: 72 | CC2: 73 | CD2: 74 | CE2: 75 | CF2: 76 | CG2: 77 | CH2: 78 | CI2: 79 | CJ2: 80 | CK2: 81 | CL2: 82 | CM2: 83 | CN2: 84 | CO2: 85 | CP2: 86 | CQ2: 87 | CR2: 88 | CS2: 89 | CT2: 90 | CU2: 91 | CV2: 92 | CW2: 93 | CX2: 94 | CY2: 95 | CZ2: 96 | DA2: 97 | DB2: 98 | DC2: 99
H4: 項目 | I4: 全体 | J4: 農業，林業 | K4: 農業 | L4: 林業 | M4: 非農林業 | N4: 漁業 | O4: 漁業(水産養殖業を除く) | P4: 水産養殖業 | Q4: 鉱業，採石業，砂利採取業 | R4: 建設業 | S4: 製造業 | T4: 食料品製造業 | U4: 飲料・たばこ・飼料製造業 | V4: 繊維工業 | W4: 木材・木製品製造業(家具を除く) | X4: 家具・装備品製造業 | Y4: パルプ・紙・紙加工品製造業 | Z4: 印刷・同関連業 | AA4: 化学工業 | AB4: 石油製品・石炭製品製造業 | AC4: プラスチック製品製造業(別掲を除く) | AD4: ゴム製品製造業 | AE4: なめし革・同製品・毛皮製造業 | AF4: 窯業・土石製品製造業 | AG4: 鉄鋼業 | AH4: 非鉄金属製造業 | AI4: 金属製品製造業 | AJ4: はん用機械器具製造業 | AK4: 生産用機械器具製造業 | AL4: 業務用機械器具製造業 | AM4: 電子部品・デバイス・電子回路製造業 | AN4: 電気機械器具製造業 | AO4: 情報通信機械器具製造業 | AP4: 輸送用機械器具製造業 | AQ4: その他の製造業 | AR4: 電気・ガス・熱供給・水道業 | AS4: 情報通信業 | AT4: 通信業 | AU4: 放送業 | AV4: 情報サービス業 | AW4: インターネット附随サービス業 | AX4: 映像・音声・文字情報制作業 | AY4: 運輸業，郵便業 | AZ4: 鉄道業 | BA4: 道路旅客運送業 | BB4: 道路貨物運送業 | BC4: 水運業 | BD4: 航空運輸業 | BE4: 倉庫業 | BF4: 運輸に附帯するサービス業 | BG4: 郵便業(信書便事業を含む) | BH4: 卸売業，小売業 | BI4: 卸売業 | BJ4: 各種商品小売業 | BK4: 織物・衣服・身の回り品小売業 | BL4: 飲食料品小売業 | BM4: 機械器具小売業 | BN4: その他の小売業 | BO4: 金融業，保険業 | BP4: 不動産業，物品賃貸業 | BQ4: 不動産業 | BR4: 物品賃貸業 | BS4: 学術研究，専門・技術サービス業 | BT4: 学術・開発研究機関 | BU4: 専門サービス業(他に分類されないもの) | BV4: 広告業 | BW4: 技術サービス業(他に分類されないもの) | BX4: 宿泊業，飲食サービス業 | BY4: 宿泊業 | BZ4: 飲食店 | CA4: 持ち帰り・配達飲食サービス業 | CB4: 生活関連サービス業，娯楽業 | CC4: 洗濯・理容・美容・浴場業 | CD4: その他の生活関連サービス業 | CE4: 娯楽業 | CF4: 教育，学習支援業 | CG4: 学校教育 | CH4: その他の教育，学習支援業 | CI4: 医療，福祉 | CJ4: 医療業 | CK4: 保健衛生 | CL4: 社会保険・社会福祉・介護事業 | CM4: 複合サービス事業 | CN4: 郵便局 | CO4: 協同組合(他に分類されないもの) | CP4: サービス業(他に分類されないもの) | CQ4: 廃棄物処理業 | CR4: 自動車整備業 | CS4: 機械等修理業(別掲を除く) | CT4: 職業紹介・労働者派遣業 | CU4: その他の事業サービス業 | CV4: 政治・経済・文化団体 | CW4: 宗教 | CX4: その他のサービス業 | CY4: 外国公務 | CZ4: 公務(他に分類されるものを除く) | DA4: 国家公務 | DB4: 地方公務 | DC4: 分類不能の産業
A5: 02021 | B5: 97*D0 | D5: 01 | E5: 0000 | F5: 1 | H5: 男女計 | I5: 6723 | J5: 192 | K5: 185 | L5: 7 | M5: 6531 | N5: 13 | O5: 9 | P5: 4 | Q5: 2 | R5: 479 | S5: 1044 | T5: 133 | U5: 15 | V5: 35 | W5: 12 | X5: 12 | Y5: 23 | Z5: 38 | AA5: 68 | AB5: 4 | AC5: 50 | AD5: 16 | AE5: 4 | AF5: 32 | AG5: 24 | AH5: 17 | AI5: 97 | AJ5: 37 | AK5: 70 | AL5: 35 | AM5: 64 | AN5: 64 | AO5: 20 | AP5: 132 | AQ5: 43 | AR5: 32 | AS5: 272 | AT5: 20 | AU5: 8 | AV5: 186 | AW5: 20 | AX5: 37 | AY5: 351 | AZ5: 26 | BA5: 41 | BB5: 201 | BC5: 5 | BD5: 6 | BE5: 27 | BF5: 33 | BG5: 12 | BH5: 1044 | BI5: 311 | BJ5: 37 | BK5: 58 | BL5: 287 | BM5: 93 | BN5: 258 | BO5: 160 | BP5: 141 | BQ5: 112 | BR5: 28 | BS5: 254 | BT5: 19 | BU5: 114 | BV5: 18 | BW5: 103 | BX5: 381 | BY5: 53 | BZ5: 269 | CA5: 59 | CB5: 225 | CC5: 107 | CD5: 45 | CE5: 74 | CF5: 349 | CG5: 240 | CH5: 109 | CI5: 908 | CJ5: 433 | CK5: 15 | CL5: 460 | CM5: 50 | CN5: 27 | CO5: 23 | CP5: 463 | CQ5: 34 | CR5: 29 | CS5: 26 | CT5: 37 | CU5: 286 | CV5: 26 | CW5: 19 | CX5: 5 | CY5: 2 | CZ5: 251 | DA5: 69 | DB5: 183 | DC5: 113
A6: 02021 | B6: 97*D0 | D6: 01 | E6: 0000 | F6: 13 | H6: 男女計_15～64歳 | I6: 5810 | J6: 91 | K6: 86 | L6: 5 | M6: 5719 | N6: 8 | O6: 5 | P6: 3 | Q6: 2 | R6: 398 | S6: 954 | T6: 117 | U6: 14 | V6: 27 | W6: 10 | X6: 10 | Y6: 21 | Z6: 34 | AA6: 66 | AB6: 4 | AC6: 46 | AD6: 14 | AE6: 3 | AF6: 29 | AG6: 22 | AH6: 16 | AI6: 84 | AJ6: 34 | AK6: 64 | AL6: 33 | AM6: 62 | AN6: 59 | AO6: 19 | AP6: 127 | AQ6: 39 | AR6: 31 | AS6: 266 | AT6: 20 | AU6: 8 | AV6: 183 | AW6: 20 | AX6: 35 | AY6: 310 | AZ6: 25 | BA6: 28 | BB6: 181 | BC6: 4 | BD6: 6 | BE6: 25 | BF6: 30 | BG6: 12 | BH6: 917 | BI6: 279 | BJ6: 34 | BK6: 51 | BL6: 245 | BM6: 84 | BN6: 225 | BO6: 152 | BP6: 103 | BQ6: 77 | BR6: 26 | BS6: 219 | BT6: 18 | BU6: 98 | BV6: 17 | BW6: 87 | BX6: 322 | BY6: 43 | BZ6: 232 | CA6: 48 | CB6: 182 | CC6: 84 | CD6: 35 | CE6: 63 | CF6: 315 | CG6: 222 | CH6: 93 | CI6: 803 | CJ6: 399 | CK6: 14 | CL6: 390 | CM6: 48 | CN6: 26 | CO6: 21 | CP6: 358 | CQ6: 29 | CR6: 23 | CS6: 22 | CT6: 34 | CU6: 211 | CV6: 21 | CW6: 12 | CX6: 3 | CY6: 2 | CZ6: 240 | DA6: 67 | DB6: 173 | DC6: 92
A7: 02021 | B7: 97*D0 | D7: 01 | E7: 0000 | F7: 2 | H7: 男女計_15～19歳 | I7: 106 | J7: 1 | K7: 1 | L7: - | M7: 105 | N7: 0 | O7: 0 | P7: - | Q7: - | R7: 3 | S7: 10 | T7: 2 | U7: 0 | V7: 0 | W7: 0 | X7: 0 | Y7: 0 | Z7: 0 | AA7: 1 | AB7: 0 | AC7: 0 | AD7: 0 | AE7: 0 | AF7: 0 | AG7: 0 | AH7: 0 | AI7: 1 | AJ7: 0 | AK7: 1 | AL7: 0 | AM7: 1 | AN7: 0 | AO7: 0 | AP7: 2 | AQ7: 0 | AR7: 0 | AS7: 0 | AT7: 0 | AU7: 0 | AV7: 0 | AW7: 0 | AX7: 0 | AY7: 2 | AZ7: 0 | BA7: 0 | BB7: 2 | BC7: 0 | BD7: - | BE7: 0 | BF7: 0 | BG7: 0 | BH7: 30 | BI7: 1 | BJ7: 1 | BK7: 1 | BL7: 19 | BM7: 1 | BN7: 7 | BO7: 0 | BP7: 0 | BQ7: 0 | BR7: 0 | BS7: 1 | BT7: 0 | BU7: 0 | BV7: 0 | BW7: 0 | BX7: 39 | BY7: 1 | BZ7: 36 | CA7: 2 | CB7: 4 | CC7: 1 | CD7: 0 | CE7: 2 | CF7: 6 | CG7: 0 | CH7: 5 | CI7: 3 | CJ7: 1 | CK7: 0 | CL7: 2 | CM7: 0 | CN7: 0 | CO7: 0 | CP7: 3 | CQ7: 0 | CR7: 0 | CS7: 0 | CT7: 0 | CU7: 2 | CV7: 0 | CW7: 0 | CX7: 0 | CY7: - | CZ7: 2 | DA7: 1 | DB7: 1 | DC7: 2
A8: 02021 | B8: 97*D0 | D8: 01 | E8: 0000 | F8: 3 | H8: 男女計_20～24歳 | I8: 441 | J8: 5 | K8: 4 | L8: 0 | M8: 437 | N8: 0 | O8: 0 | P8: 0 | Q8: 0 | R8: 21 | S8: 59 | T8: 9 | U8: 1 | V8: 1 | W8: 1 | X8: 0 | Y8: 1 | Z8: 2 | AA8: 5 | AB8: 1 | AC8: 3 | AD8: 1 | AE8: 0 | AF8: 1 | AG8: 1 | AH8: 1 | AI8: 5 | AJ8: 2 | AK8: 4 | AL8: 1 | AM8: 4 | AN8: 3 | AO8: 1 | AP8: 10 | AQ8: 2 | AR8: 1 | AS8: 19 | AT8: 2 | AU8: 0 | AV8: 13 | AW8: 1 | AX8: 2 | AY8: 15 | AZ8: 2 | BA8: 0 | BB8: 8 | BC8: 0 | BD8: 0 | BE8: 1 | BF8: 2 | BG8: 0 | BH8: 85 | BI8: 12 | BJ8: 3 | BK8: 6 | BL8: 33 | BM8: 8 | BN8: 23 | BO8: 7 | BP8: 5 | BQ8: 3 | BR8: 2 | BS8: 11 | BT8: 1 | BU8: 3 | BV8: 1 | BW8: 6 | BX8: 60 | BY8: 5 | BZ8: 50 | CA8: 6 | CB8: 20 | CC8: 7 | CD8: 2 | CE8: 11 | CF8: 31 | CG8: 14 | CH8: 17 | CI8: 54 | CJ8: 30 | CK8: 1 | CL8: 23 | CM8: 3 | CN8: 1 | CO8: 2 | CP8: 20 | CQ8: 1 | CR8: 1 | CS8: 1 | CT8: 3 | CU8: 13 | CV8: 0 | CW8: 0 | CX8: 0 | CY8: 0 | CZ8: 16 | DA8: 7 | DB8: 9 | DC8: 9
A9: 02021 | B9: 97*D0 | D9: 01 | E9: 0000 | F9: 4 | H9: 男女計_25～29歳 | I9: 558 | J9: 5 | K9: 5 | L9: 0 | M9: 553 | N9: 1 | O9: 0 | P9: 0 | Q9: 0 | R9: 32 | S9: 91 | T9: 12 | U9: 2 | V9: 2 | W9: 1 | X9: 1 | Y9: 2 | Z9: 2 | AA9: 6 | AB9: 1 | AC9: 3 | AD9: 1 | AE9: 0 | AF9: 2 | AG9: 2 | AH9: 1 | AI9: 8 | AJ9: 4 | AK9: 7 | AL9: 2 | AM9: 6 | AN9: 5 | AO9: 2 | AP9: 14 | AQ9: 4 | AR9: 3 | AS9: 43 | AT9: 3 | AU9: 1 | AV9: 31 | AW9: 4 | AX9: 4 | AY9: 21 | AZ9: 3 | BA9: 1 | BB9: 10 | BC9: 0 | BD9: 1 | BE9: 2 | BF9: 3 | BG9: 1 | BH9: 81 | BI9: 25 | BJ9: 2 | BK9: 6 | BL9: 17 | BM9: 9 | BN9: 21 | BO9: 20 | BP9: 9 | BQ9: 6 | BR9: 2 | BS9: 23 | BT9: 2 | BU9: 9 | BV9: 2 | BW9: 10 | BX9: 21 | BY9: 5 | BZ9: 13 | CA9: 3 | CB9: 18 | CC9: 7 | CD9: 3 | CE9: 7 | CF9: 30 | CG9: 23 | CH9: 7 | CI9: 87 | CJ9: 49 | CK9: 1 | CL9: 37 | CM9: 3 | CN9: 2 | CO9: 2 | CP9: 34 | CQ9: 2 | CR9: 2 | CS9: 2 | CT9: 7 | CU9: 19 | CV9: 1 | CW9: 1 | CX9: 0 | CY9: 0 | CZ9: 27 | DA9: 8 | DB9: 19 | DC9: 9
A10: 02021 | B10: 97*D0 | D10: 01 | E10: 0000 | F10: 5 | H10: 男女計_30～34歳 | I10: 552 | J10: 7 | K10: 6 | L10: 0 | M10: 545 | N10: 0 | O10: 0 | P10: 0 | Q10: 0 | R10: 30 | S10: 95 | T10: 11 | U10: 1 | V10: 2 | W10: 1 | X10: 1 | Y10: 2 | Z10: 3 | AA10: 7 | AB10: 0 | AC10: 5 | AD10: 1 | AE10: 0 | AF10: 2 | AG10: 3 | AH10: 1 | AI10: 9 | AJ10: 4 | AK10: 7 | AL10: 3 | AM10: 5 | AN10: 6 | AO10: 1 | AP10: 15 | AQ10: 4 | AR10: 3 | AS10: 35 | AT10: 2 | AU10: 1 | AV10: 24 | AW10: 4 | AX10: 4 | AY10: 24 | AZ10: 3 | BA10: 1 | BB10: 12 | BC10: 0 | BD10: 1 | BE10: 3 | BF10: 4 | BG10: 1 | BH10: 81 | BI10: 25 | BJ10: 2 | BK10: 5 | BL10: 18 | BM10: 9 | BN10: 22 | BO10: 14 | BP10: 10 | BQ10: 8 | BR10: 3 | BS10: 25 | BT10: 2 | BU10: 12 | BV10: 3 | BW10: 9 | BX10: 21 | BY10: 4 | BZ10: 15 | CA10: 3 | CB10: 17 | CC10: 7 | CD10: 3 | CE10: 8 | CF10: 31 | CG10: 25 | CH10: 6 | CI10: 81 | CJ10: 44 | CK10: 1 | CL10: 35 | CM10: 4 | CN10: 2 | CO10: 2 | CP10: 34 | CQ10: 2 | CR10: 2 | CS10: 2 | CT10: 6 | CU10: 19 | CV10: 2 | CW10: 1 | CX10: 0 | CY10: 0 | CZ10: 29 | DA10: 7 | DB10: 22 | DC10: 9
A11: 02021 | B11: 97*D0 | D11: 01 | E11: 0000 | F11: 6 | H11: 男女計_35～39歳 | I11: 619 | J11: 9 | K11: 8 | L11: 1 | M11: 610 | N11: 1 | O11: 0 | P11: 0 | Q11: 0 | R11: 39 | S11: 105 | T11: 12 | U11: 2 | V11: 3 | W11: 1 | X11: 1 | Y11: 2 | Z11: 3 | AA11: 8 | AB11: 0 | AC11: 5 | AD11: 2 | AE11: 0 | AF11: 3 | AG11: 3 | AH11: 2 | AI11: 9 | AJ11: 4 | AK11: 7 | AL11: 4 | AM11: 7 | AN11: 6 | AO11: 2 | AP11: 14 | AQ11: 5 | AR11: 2 | AS11: 36 | AT11: 2 | AU11: 1 | AV11: 25 | AW11: 3 | AX11: 4 | AY11: 29 | AZ11: 3 | BA11: 1 | BB11: 16 | BC11: 0 | BD11: 1 | BE11: 3 | BF11: 3 | BG11: 1 | BH11: 93 | BI11: 31 | BJ11: 3 | BK11: 7 | BL11: 20 | BM11: 10 | BN11: 23 | BO11: 18 | BP11: 10 | BQ11: 7 | BR11: 3 | BS11: 27 | BT11: 2 | BU11: 14 | BV11: 2 | BW11: 9 | BX11: 27 | BY11: 4 | BZ11: 19 | CA11: 5 | CB11: 22 | CC11: 11 | CD11: 4 | CE11: 7 | CF11: 30 | CG11: 23 | CH11: 8 | CI11: 93 | CJ11: 47 | CK11: 2 | CL11: 44 | CM11: 5 | CN11: 3 | CO11: 2 | CP11: 36 | CQ11: 3 | CR11: 2 | CS11: 2 | CT11: 5 | CU11: 21 | CV11: 2 | CW11: 1 | CX11: 0 | CY11: 0 | CZ11: 27 | DA11: 7 | DB11: 20 | DC11: 9
A12: 02021 | B12: 97*D0 | D12: 01 | E12: 0000 | F12: 7 | H12: 男女計_40～44歳 | I12: 694 | J12: 10 | K12: 10 | L12: 0 | M12: 684 | N12: 1 | O12: 1 | P12: 0 | Q12: 0 | R12: 48 | S12: 120 | T12: 14 | U12: 2 | V12: 3 | W12: 1 | X12: 1 | Y12: 2 | Z12: 5 | AA12: 8 | AB12: 0 | AC12: 6 | AD12: 2 | AE12: 1 | AF12: 4 | AG12: 3 | AH12: 2 | AI12: 10 | AJ12: 4 | AK12: 8 | AL12: 4 | AM12: 8 | AN12: 7 | AO12: 2 | AP12: 17 | AQ12: 5 | AR12: 3 | AS12: 34 | AT12: 2 | AU12: 1 | AV12: 23 | AW12: 3 | AX12: 5 | AY12: 38 | AZ12: 3 | BA12: 2 | BB12: 23 | BC12: 0 | BD12: 1 | BE12: 3 | BF12: 4 | BG12: 2 | BH12: 105 | BI12: 34 | BJ12: 4 | BK12: 7 | BL12: 23 | BM12: 10 | BN12: 27 | BO12: 16 | BP12: 13 | BQ12: 10 | BR12: 3 | BS12: 28 | BT12: 2 | BU12: 14 | BV12: 3 | BW12: 9 | BX12: 31 | BY12: 4 | BZ12: 22 | CA12: 5 | CB12: 22 | CC12: 12 | CD12: 3 | CE12: 7 | CF12: 34 | CG12: 25 | CH12: 9 | CI12: 102 | CJ12: 52 | CK12: 1 | CL12: 49 | CM12: 6 | CN12: 3 | CO12: 3 | CP12: 42 | CQ12: 4 | CR12: 3 | CS12: 3 | CT12: 4 | CU12: 24 | CV12: 2 | CW12: 2 | CX12: 1 | CY12: 0 | CZ12: 29 | DA12: 8 | DB12: 21 | DC12: 11
A13: 02021 | B13: 97*D0 | D13: 01 | E13: 0000 | F13: 8 | H13: 男女計_45～49歳 | I13: 830 | J13: 12 | K13: 11 | L13: 1 | M13: 818 | N13: 1 | O13: 1 | P13: 0 | Q13: 0 | R13: 68 | S13: 145 | T13: 17 | U13: 2 | V13: 4 | W13: 2 | X13: 1 | Y13: 3 | Z13: 6 | AA13: 10 | AB13: 0 | AC13: 7 | AD13: 2 | AE13: 0 | AF13: 5 | AG13: 3 | AH13: 3 | AI13: 13 | AJ13: 5 | AK13: 10 | AL13: 6 | AM13: 10 | AN13: 9 | AO13: 3 | AP13: 17 | AQ13: 5 | AR13: 5 | AS13: 34 | AT13: 3 | AU13: 1 | AV13: 23 | AW13: 3 | AX13: 4 | AY13: 51 | AZ13: 4 | BA13: 4 | BB13: 32 | BC13: 0 | BD13: 1 | BE13: 4 | BF13: 4 | BG13: 2 | BH13: 128 | BI13: 45 | BJ13: 4 | BK13: 6 | BL13: 29 | BM13: 12 | BN13: 32 | BO13: 20 | BP13: 14 | BQ13: 10 | BR13: 4 | BS13: 32 | BT13: 3 | BU13: 15 | BV13: 2 | BW13: 12 | BX13: 37 | BY13: 5 | BZ13: 25 | CA13: 7 | CB13: 22 | CC13: 11 | CD13: 5 | CE13: 6 | CF13: 41 | CG13: 31 | CH13: 10 | CI13: 112 | CJ13: 55 | CK13: 2 | CL13: 55 | CM13: 8 | CN13: 5 | CO13: 3 | CP13: 52 | CQ13: 5 | CR13: 4 | CS13: 4 | CT13: 4 | CU13: 29 | CV13: 3 | CW13: 2 | CX13: 0 | CY13: 0 | CZ13: 33 | DA13: 9 | DB13: 24 | DC13: 14
A14: 02021 | B14: 97*D0 | D14: 01 | E14: 0000 | F14: 9 | H14: 男女計_50～54歳 | I14: 806 | J14: 12 | K14: 11 | L14: 1 | M14: 795 | N14: 1 | O14: 1 | P14: 0 | Q14: 0 | R14: 66 | S14: 141 | T14: 16 | U14: 2 | V14: 4 | W14: 1 | X14: 2 | Y14: 4 | Z14: 5 | AA14: 9 | AB14: 0 | AC14: 7 | AD14: 2 | AE14: 1 | AF14: 5 | AG14: 3 | AH14: 3 | AI14: 13 | AJ14: 5 | AK14: 9 | AL14: 5 | AM14: 10 | AN14: 10 | AO14: 4 | AP14: 16 | AQ14: 6 | AR14: 5 | AS14: 29 | AT14: 2 | AU14: 1 | AV14: 20 | AW14: 1 | AX14: 5 | AY14: 53 | AZ14: 2 | BA14: 5 | BB14: 34 | BC14: 1 | BD14: 1 | BE14: 4 | BF14: 4 | BG14: 2 | BH14: 126 | BI14: 44 | BJ14: 6 | BK14: 5 | BL14: 31 | BM14: 11 | BN14: 30 | BO14: 22 | BP14: 15 | BQ14: 11 | BR14: 4 | BS14: 29 | BT14: 3 | BU14: 13 | BV14: 2 | BW14: 12 | BX14: 35 | BY14: 5 | BZ14: 23 | CA14: 7 | CB14: 21 | CC14: 11 | CD14: 5 | CE14: 5 | CF14: 39 | CG14: 30 | CH14: 10 | CI14: 105 | CJ14: 49 | CK14: 2 | CL14: 54 | CM14: 8 | CN14: 4 | CO14: 3 | CP14: 51 | CQ14: 5 | CR14: 4 | CS14: 4 | CT14: 3 | CU14: 30 | CV14: 3 | CW14: 2 | CX14: 0 | CY14: 1 | CZ14: 35 | DA14: 10 | DB14: 25 | DC14: 13
A15: 02021 | B15: 97*D0 | D15: 01 | E15: 0000 | F15: 10 | H15: 男女計_55～59歳 | I15: 662 | J15: 12 | K15: 11 | L15: 1 | M15: 650 | N15: 1 | O15: 1 | P15: 0 | Q15: 0 | R15: 49 | S15: 112 | T15: 13 | U15: 2 | V15: 4 | W15: 1 | X15: 1 | Y15: 2 | Z15: 4 | AA15: 8 | AB15: 0 | AC15: 6 | AD15: 1 | AE15: 0 | AF15: 4 | AG15: 2 | AH15: 2 | AI15: 10 | AJ15: 4 | AK15: 8 | AL15: 4 | AM15: 8 | AN15: 8 | AO15: 3 | AP15: 13 | AQ15: 4 | AR15: 4 | AS15: 22 | AT15: 2 | AU15: 1 | AV15: 15 | AW15: 1 | AX15: 4 | AY15: 43 | AZ15: 2 | BA15: 7 | BB15: 26 | BC15: 1 | BD15: 1 | BE15: 3 | BF15: 3 | BG15: 1 | BH15: 103 | BI15: 35 | BJ15: 5 | BK15: 4 | BL15: 28 | BM15: 7 | BN15: 23 | BO15: 21 | BP15: 13 | BQ15: 11 | BR15: 2 | BS15: 24 | BT15: 2 | BU15: 10 | BV15: 1 | BW15: 10 | BX15: 26 | BY15: 5 | BZ15: 16 | CA15: 6 | CB15: 18 | CC15: 9 | CD15: 5 | CE15: 5 | CF15: 40 | CG15: 29 | CH15: 10 | CI15: 89 | CJ15: 42 | CK15: 2 | CL15: 46 | CM15: 7 | CN15: 4 | CO15: 3 | CP15: 43 | CQ15: 4 | CR15: 3 | CS15: 2 | CT15: 2 | CU15: 26 | CV15: 3 | CW15: 2 | CX15: 1 | CY15: 0 | CZ15: 25 | DA15: 6 | DB15: 19 | DC15: 9
A16: 02021 | B16: 97*D0 | D16: 01 | E16: 0000 | F16: 11 | H16: 男女計_60～64歳 | I16: 542 | J16: 19 | K16: 18 | L16: 1 | M16: 523 | N16: 1 | O16: 1 | P16: 0 | Q16: 0 | R16: 42 | S16: 77 | T16: 11 | U16: 1 | V16: 3 | W16: 1 | X16: 1 | Y16: 2 | Z16: 3 | AA16: 5 | AB16: 0 | AC16: 4 | AD16: 1 | AE16: 0 | AF16: 3 | AG16: 2 | AH16: 1 | AI16: 7 | AJ16: 3 | AK16: 5 | AL16: 3 | AM16: 4 | AN16: 5 | AO16: 1 | AP16: 8 | AQ16: 3 | AR16: 2 | AS16: 12 | AT16: 1 | AU16: 1 | AV16: 8 | AW16: 0 | AX16: 2 | AY16: 34 | AZ16: 2 | BA16: 6 | BB16: 18 | BC16: 1 | BD16: 0 | BE16: 2 | BF16: 3 | BG16: 1 | BH16: 84 | BI16: 27 | BJ16: 4 | BK16: 3 | BL16: 27 | BM16: 5 | BN16: 18 | BO16: 13 | BP16: 13 | BQ16: 11 | BR16: 2 | BS16: 20 | BT16: 2 | BU16: 8 | BV16: 1 | BW16: 9 | BX16: 23 | BY16: 5 | BZ16: 13 | CA16: 5 | CB16: 17 | CC16: 8 | CD16: 4 | CE16: 5 | CF16: 33 | CG16: 23 | CH16: 9 | CI16: 78 | CJ16: 31 | CK16: 2 | CL16: 45 | CM16: 5 | CN16: 3 | CO16: 2 | CP16: 43 | CQ16: 4 | CR16: 2 | CS16: 2 | CT16: 2 | CU16: 27 | CV16: 4 | CW16: 2 | CX16: 1 | CY16: 0 | CZ16: 17 | DA16: 4 | DB16: 13 | DC16: 7
A17: 02021 | B17: 97*D0 | D17: 01 | E17: 0000 | F17: 12 | H17: 男女計_65歳以上 | I17: 912 | J17: 101 | K17: 99 | L17: 2 | M17: 811 | N17: 5 | O17: 4 | P17: 1 | Q17: 1 | R17: 81 | S17: 90 | T17: 16 | U17: 1 | V17: 8 | W17: 2 | X17: 2 | Y17: 2 | Z17: 5 | AA17: 2 | AB17: 0 | AC17: 4 | AD17: 1 | AE17: 1 | AF17: 4 | AG17: 2 | AH17: 1 | AI17: 13 | AJ17: 3 | AK17: 6 | AL17: 2 | AM17: 2 | AN17: 4 | AO17: 1 | AP17: 5 | AQ17: 5 | AR17: 1 | AS17: 6 | AT17: 0 | AU17: 0 | AV17: 3 | AW17: 0 | AX17: 2 | AY17: 41 | AZ17: 1 | BA17: 14 | BB17: 20 | BC17: 1 | BD17: 0 | BE17: 2 | BF17: 3 | BG17: 0 | BH17: 127 | BI17: 31 | BJ17: 3 | BK17: 7 | BL17: 43 | BM17: 10 | BN17: 33 | BO17: 8 | BP17: 38 | BQ17: 35 | BR17: 2 | BS17: 35 | BT17: 1 | BU17: 16 | BV17: 1 | BW17: 16 | BX17: 59 | BY17: 10 | BZ17: 37 | CA17: 12 | CB17: 43 | CC17: 23 | CD17: 10 | CE17: 11 | CF17: 34 | CG17: 18 | CH17: 17 | CI17: 104 | CJ17: 33 | CK17: 2 | CL17: 70 | CM17: 2 | CN17: 1 | CO17: 2 | CP17: 105 | CQ17: 5 | CR17: 6 | CS17: 3 | CT17: 2 | CU17: 75 | CV17: 5 | CW17: 7 | CX17: 1 | CY17: 0 | CZ17: 12 | DA17: 2 | DB17: 10 | DC17: 21

Sheet 男性
I1: 1 | J1: 2 | K1: 3 | L1: 4 | M1: 5 | N1: 6 | O1: 7 | P1: 8 | Q1: 9 | R1: 10 | S1: 11 | T1: 12 | U1: 13 | V1: 14 | W1: 15 | X1: 16 | Y1: 17 | Z1: 18 | AA1: 19 | AB1: 20 | AC1: 21 | AD1: 22 | AE1: 23 | AF1: 24 | AG1: 25 | AH1: 26 | AI1: 27 | AJ1: 28 | AK1: 29 | AL1: 30 | AM1: 31 | AN1: 32 | AO1: 33 | AP1: 34 | AQ1: 35 | AR1: 36 | AS1: 37 | AT1: 38 | AU1: 39 | AV1: 40 | AW1: 41 | AX1: 42 | AY1: 43 | AZ1: 44 | BA1: 45 | BB1: 46 | BC1: 47 | BD1: 48 | BE1: 49 | BF1: 50 | BG1: 51 | BH1: 52 | BI1: 53 | BJ1: 54 | BK1: 55 | BL1: 56 | BM1: 57 | BN1: 58 | BO1: 59 | BP1: 60 | BQ1: 61 | BR1: 62 | BS1: 63 | BT1: 64 | BU1: 65 | BV1: 66 | BW1: 67 | BX1: 68 | BY1: 69 | BZ1: 70 | CA1: 71 | CB1: 72 | CC1: 73 | CD1: 74 | CE1: 75 | CF1: 76 | CG1: 77 | CH1: 78 | CI1: 79 | CJ1: 80 | CK1: 81 | CL1: 82 | CM1: 83 | CN1: 84 | CO1: 85 | CP1: 86 | CQ1: 87 | CR1: 88 | CS1: 89 | CT1: 90 | CU1: 91 | CV1: 92 | CW1: 93 | CX1: 94 | CY1: 95 | CZ1: 96 | DA1: 97 | DB1: 98 | DC1: 99
I2: 1 | J2: 2 | K2: 3 | L2: 4 | M2: 5 | N2: 6 | O2: 7 | P2: 8 | Q2: 9 | R2: 10 | S2: 11 | T2: 12 | U2: 13 | V2: 14 | W2: 15 | X2: 16 | Y2: 17 | Z2: 18 | AA2: 19 | AB2: 20 | AC2: 21 | AD2: 22 | AE2: 23 | AF2: 24 | AG2: 25 | AH2: 26 | AI2: 27 | AJ2: 28 | AK2: 29 | AL2: 30 | AM2: 31 | AN2: 32 | AO2: 33 | AP2: 34 | AQ2: 35 | AR2: 36 | AS2: 37 | AT2: 38 | AU2: 39 | AV2: 40 | AW2: 41 | AX2: 42 | AY2: 43 | AZ2: 44 | BA2: 45 | BB2: 46 | BC2: 47 | BD2: 48 | BE2: 49 | BF2: 50 | BG2: 51 | BH2: 52 | BI2: 53 | BJ2: 54 | BK2: 55 | BL2: 56 | BM2: 57 | BN2: 58 | BO2: 59 | BP2: 60 | BQ2: 61 | BR2: 62 | BS2: 63 | BT2: 64 | BU2: 65 | BV2: 66 | BW2: 67 | BX2: 68 | BY2: 69 | BZ2: 70 | CA2: 71 | CB2: 72 | CC2: 73 | CD2: 74 | CE2: 75 | CF2: 76 | CG2: 77 | CH2: 78 | CI2: 79 | CJ2: 80 | CK2: 81 | CL2: 82 | CM2: 83 | CN2: 84 | CO2: 85 | CP2: 86 | CQ2: 87 | CR2: 88 | CS2: 89 | CT2: 90 | CU2: 91 | CV2: 92 | CW2: 93 | CX2: 94 | CY2: 95 | CZ2: 96 | DA2: 97 | DB2: 98 | DC2: 99
H4: 項目 | I4: 全体 | J4: 農業，林業 | K4: 農業 | L4: 林業 | M4: 非農林業 | N4: 漁業 | O4: 漁業(水産養殖業を除く) | P4: 水産養殖業 | Q4: 鉱業，採石業，砂利採取業 | R4: 建設業 | S4: 製造業 | T4: 食料品製造業 | U4: 飲料・たばこ・飼料製造業 | V4: 繊維工業 | W4: 木材・木製品製造業(家具を除く) | X4: 家具・装備品製造業 | Y4: パルプ・紙・紙加工品製造業 | Z4: 印刷・同関連業 | AA4: 化学工業 | AB4: 石油製品・石炭製品製造業 | AC4: プラスチック製品製造業(別掲を除く) | AD4: ゴム製品製造業 | AE4: なめし革・同製品・毛皮製造業 | AF4: 窯業・土石製品製造業 | AG4: 鉄鋼業 | AH4: 非鉄金属製造業 | AI4: 金属製品製造業 | AJ4: はん用機械器具製造業 | AK4: 生産用機械器具製造業 | AL4: 業務用機械器具製造業 | AM4: 電子部品・デバイス・電子回路製造業 | AN4: 電気機械器具製造業 | AO4: 情報通信機械器具製造業 | AP4: 輸送用機械器具製造業 | AQ4: その他の製造業 | AR4: 電気・ガス・熱供給・水道業 | AS4: 情報通信業 | AT4: 通信業 | AU4: 放送業 | AV4: 情報サービス業 | AW4: インターネット附随サービス業 | AX4: 映像・音声・文字情報制作業 | AY4: 運輸業，郵便業 | AZ4: 鉄道業 | BA4: 道路旅客運送業 | BB4: 道路貨物運送業 | BC4: 水運業 | BD4: 航空運輸業 | BE4: 倉庫業 | BF4: 運輸に附帯するサービス業 | BG4: 郵便業(信書便事業を含む) | BH4: 卸売業，小売業 | BI4: 卸売業 | BJ4: 各種商品小売業 | BK4: 織物・衣服・身の回り品小売業 | BL4: 飲食料品小売業 | BM4: 機械器具小売業 | BN4: その他の小売業 | BO4: 金融業，保険業 | BP4: 不動産業，物品賃貸業 | BQ4: 不動産業 | BR4: 物品賃貸業 | BS4: 学術研究，専門・技術サービス業 | BT4: 学術・開発研究機関 | BU4: 専門サービス業(他に分類されないもの) | BV4: 広告業 | BW4: 技術サービス業(他に分類されないもの) | BX4: 宿泊業，飲食サービス業 | BY4: 宿泊業 | BZ4: 飲食店 | CA4: 持ち帰り・配達飲食サービス業 | CB4: 生活関連サービス業，娯楽業 | CC4: 洗濯・理容・美容・浴場業 | CD4: その他の生活関連サービス業 | CE4: 娯楽業 | CF4: 教育，学習支援業 | CG4: 学校教育 | CH4: その他の教育，学習支援業 | CI4: 医療，福祉 | CJ4: 医療業 | CK4: 保健衛生 | CL4: 社会保険・社会福祉・介護事業 | CM4: 複合サービス事業 | CN4: 郵便局 | CO4: 協同組合(他に分類されないもの) | CP4: サービス業(他に分類されないもの) | CQ4: 廃棄物処理業 | CR4: 自動車整備業 | CS4: 機械等修理業(別掲を除く) | CT4: 職業紹介・労働者派遣業 | CU4: その他の事業サービス業 | CV4: 政治・経済・文化団体 | CW4: 宗教 | CX4: その他のサービス業 | CY4: 外国公務 | CZ4: 公務(他に分類されるものを除く) | DA4: 国家公務 | DB4: 地方公務 | DC4: 分類不能の産業
A5: 02021 | B5: 97*D0 | D5: 01 | E5: 0000 | F5: 1 | H5: 男性 | I5: 3699 | J5: 118 | K5: 113 | L5: 5 | M5: 3580 | N5: 10 | O5: 8 | P5: 3 | Q5: 2 | R5: 394 | S5: 732 | T5: 65 | U5: 10 | V5: 14 | W5: 9 | X5: 9 | Y5: 16 | Z5: 25 | AA5: 48 | AB5: 4 | AC5: 32 | AD5: 11 | AE5: 2 | AF5: 25 | AG5: 20 | AH5: 13 | AI5: 75 | AJ5: 30 | AK5: 58 | AL5: 24 | AM5: 45 | AN5: 45 | AO5: 15 | AP5: 109 | AQ5: 26 | AR5: 26 | AS5: 195 | AT5: 15 | AU5: 5 | AV5: 141 | AW5: 12 | AX5: 22 | AY5: 274 | AZ5: 23 | BA5: 37 | BB5: 160 | BC5: 4 | BD5: 3 | BE5: 16 | BF5: 22 | BG5: 9 | BH5: 497 | BI5: 205 | BJ5: 11 | BK5: 14 | BL5: 99 | BM5: 67 | BN5: 101 | BO5: 73 | BP5: 83 | BQ5: 65 | BR5: 18 | BS5: 158 | BT5: 12 | BU5: 61 | BV5: 11 | BW5: 74 | BX5: 145 | BY5: 23 | BZ5: 106 | CA5: 16 | CB5: 89 | CC5: 31 | CD5: 19 | CE5: 40 | CF5: 145 | CG5: 100 | CH5: 46 | CI5: 227 | CJ5: 115 | CK5: 4 | CL5: 108 | CM5: 29 | CN5: 16 | CO5: 13 | CP5: 273 | CQ5: 28 | CR5: 23 | CS5: 22 | CT5: 19 | CU5: 153 | CV5: 12 | CW5: 11 | CX5: 2 | CY5: 2 | CZ5: 171 | DA5: 52 | DB5: 119 | DC5: 58
A6: 02021 | B6: 97*D0 | D6: 01 | E6: 0000 | F6: 13 | H6: 男性_15～64歳 | I6: 3161 | J6: 56 | K6: 52 | L6: 4 | M6: 3105 | N6: 7 | O6: 5 | P6: 2 | Q6: 2 | R6: 325 | S6: 673 | T6: 58 | U6: 10 | V6: 10 | W6: 7 | X6: 7 | Y6: 15 | Z6: 22 | AA6: 46 | AB6: 3 | AC6: 30 | AD6: 10 | AE6: 2 | AF6: 23 | AG6: 19 | AH6: 12 | AI6: 65 | AJ6: 28 | AK6: 53 | AL6: 23 | AM6: 44 | AN6: 42 | AO6: 15 | AP6: 105 | AQ6: 23 | AR6: 25 | AS6: 190 | AT6: 14 | AU6: 5 | AV6: 138 | AW6: 12 | AX6: 20 | AY6: 239 | AZ6: 22 | BA6: 24 | BB6: 144 | BC6: 3 | BD6: 3 | BE6: 14 | BF6: 20 | BG6: 9 | BH6: 433 | BI6: 183 | BJ6: 10 | BK6: 12 | BL6: 84 | BM6: 60 | BN6: 84 | BO6: 68 | BP6: 58 | BQ6: 42 | BR6: 16 | BS6: 130 | BT6: 11 | BU6: 49 | BV6: 10 | BW6: 61 | BX6: 124 | BY6: 19 | BZ6: 93 | CA6: 12 | CB6: 70 | CC6: 24 | CD6: 13 | CE6: 33 | CF6: 127 | CG6: 89 | CH6: 38 | CI6: 192 | CJ6: 99 | CK6: 4 | CL6: 89 | CM6: 28 | CN6: 15 | CO6: 13 | CP6: 204 | CQ6: 24 | CR6: 18 | CS6: 19 | CT6: 17 | CU6: 107 | CV6: 8 | CW6: 7 | CX6: 1 | CY6: 2 | CZ6: 162 | DA6: 51 | DB6: 112 | DC6: 47
A7: 02021 | B7: 97*D0 | D7: 01 | E7: 0000 | F7: 2 | H7: 男性_15～19歳 | I7: 51 | J7: 0 | K7: 0 | L7: - | M7: 50 | N7: 0 | O7: 0 | P7: - | Q7: - | R7: 3 | S7: 6 | T7: 1 | U7: 0 | V7: 0 | W7: 0 | X7: 0 | Y7: 0 | Z7: 0 | AA7: 1 | AB7: 0 | AC7: 0 | AD7: 0 | AE7: - | AF7: 0 | AG7: 0 | AH7: 0 | AI7: 1 | AJ7: 0 | AK7: 0 | AL7: 0 | AM7: 0 | AN7: 0 | AO7: 0 | AP7: 1 | AQ7: 0 | AR7: 0 | AS7: 0 | AT7: - | AU7: - | AV7: 0 | AW7: - | AX7: 0 | AY7: 2 | AZ7: 0 | BA7: 0 | BB7: 1 | BC7: 0 | BD7: - | BE7: 0 | BF7: 0 | BG7: 0 | BH7: 13 | BI7: 1 | BJ7: 0 | BK7: 0 | BL7: 8 | BM7: 1 | BN7: 3 | BO7: 0 | BP7: 0 | BQ7: 0 | BR7: 0 | BS7: 0 | BT7: 0 | BU7: 0 | BV7: 0 | BW7: 0 | BX7: 16 | BY7: 0 | BZ7: 15 | CA7: 1 | CB7: 2 | CC7: 0 | CD7: 0 | CE7: 1 | CF7: 3 | CG7: 0 | CH7: 3 | CI7: 1 | CJ7: 0 | CK7: - | CL7: 1 | CM7: 0 | CN7: 0 | CO7: 0 | CP7: 1 | CQ7: 0 | CR7: 0 | CS7: 0 | CT7: 0 | CU7: 1 | CV7: 0 | CW7: 0 | CX7: 0 | CY7: - | CZ7: 2 | DA7: 1 | DB7: 0 | DC7: 1
A8: 02021 | B8: 97*D0 | D8: 01 | E8: 0000 | F8: 3 | H8: 男性_20～24歳 | I8: 222 | J8: 3 | K8: 3 | L8: 0 | M8: 219 | N8: 0 | O8: 0 | P8: 0 | Q8: 0 | R8: 18 | S8: 39 | T8: 4 | U8: 0 | V8: 0 | W8: 0 | X8: 0 | Y8: 1 | Z8: 1 | AA8: 3 | AB8: 1 | AC8: 1 | AD8: 0 | AE8: 0 | AF8: 1 | AG8: 1 | AH8: 0 | AI8: 4 | AJ8: 2 | AK8: 4 | AL8: 1 | AM8: 2 | AN8: 2 | AO8: 1 | AP8: 8 | AQ8: 1 | AR8: 1 | AS8: 11 | AT8: 1 | AU8: 0 | AV8: 8 | AW8: 1 | AX8: 1 | AY8: 11 | AZ8: 2 | BA8: 0 | BB8: 6 | BC8: 0 | BD8: 0 | BE8: 1 | BF8: 1 | BG8: 0 | BH8: 41 | BI8: 7 | BJ8: 2 | BK8: 1 | BL8: 16 | BM8: 5 | BN8: 10 | BO8: 3 | BP8: 3 | BQ8: 2 | BR8: 1 | BS8: 5 | BT8: 0 | BU8: 1 | BV8: 0 | BW8: 3 | BX8: 27 | BY8: 2 | BZ8: 22 | CA8: 3 | CB8: 8 | CC8: 1 | CD8: 1 | CE8: 6 | CF8: 14 | CG8: 4 | CH8: 10 | CI8: 11 | CJ8: 5 | CK8: 0 | CL8: 5 | CM8: 1 | CN8: 0 | CO8: 1 | CP8: 12 | CQ8: 1 | CR8: 1 | CS8: 1 | CT8: 1 | CU8: 7 | CV8: 0 | CW8: 0 | CX8: 0 | CY8: 0 | CZ8: 10 | DA8: 5 | DB8: 5 | DC8: 4
A9: 02021 | B9: 97*D0 | D9: 01 | E9: 0000 | F9: 4 | H9: 男性_25～29歳 | I9: 295 | J9: 4 | K9: 3 | L9: 0 | M9: 292 | N9: 1 | O9: 0 | P9: 0 | Q9: 0 | R9: 26 | S9: 64 | T9: 6 | U9: 1 | V9: 1 | W9: 0 | X9: 1 | Y9: 1 | Z9: 1 | AA9: 4 | AB9: 1 | AC9: 2 | AD9: 1 | AE9: 0 | AF9: 2 | AG9: 1 | AH9: 1 | AI9: 6 | AJ9: 3 | AK9: 6 | AL9: 2 | AM9: 4 | AN9: 4 | AO9: 1 | AP9: 12 | AQ9: 2 | AR9: 3 | AS9: 28 | AT9: 2 | AU9: 1 | AV9: 21 | AW9: 2 | AX9: 2 | AY9: 15 | AZ9: 2 | BA9: 1 | BB9: 7 | BC9: 0 | BD9: 0 | BE9: 1 | BF9: 2 | BG9: 0 | BH9: 37 | BI9: 14 | BJ9: 1 | BK9: 1 | BL9: 8 | BM9: 6 | BN9: 7 | BO9: 9 | BP9: 4 | BQ9: 3 | BR9: 1 | BS9: 12 | BT9: 1 | BU9: 4 | BV9: 1 | BW9: 6 | BX9: 9 | BY9: 2 | BZ9: 6 | CA9: 1 | CB9: 7 | CC9: 2 | CD9: 1 | CE9: 4 | CF9: 12 | CG9: 9 | CH9: 3 | CI9: 24 | CJ9: 13 | CK9: 0 | CL9: 11 | CM9: 2 | CN9: 1 | CO9: 1 | CP9: 18 | CQ9: 1 | CR9: 2 | CS9: 2 | CT9: 3 | CU9: 10 | CV9: 0 | CW9: 1 | CX9: - | CY9: 0 | CZ9: 17 | DA9: 6 | DB9: 12 | DC9: 5
A10: 02021 | B10: 97*D0 | D10: 01 | E10: 0000 | F10: 5 | H10: 男性_30～34歳 | I10: 305 | J10: 5 | K10: 5 | L10: 0 | M10: 300 | N10: 0 | O10: 0 | P10: 0 | Q10: 0 | R10: 24 | S10: 69 | T10: 6 | U10: 1 | V10: 1 | W10: 1 | X10: 0 | Y10: 2 | Z10: 2 | AA10: 5 | AB10: 0 | AC10: 3 | AD10: 1 | AE10: 0 | AF10: 2 | AG10: 2 | AH10: 1 | AI10: 7 | AJ10: 3 | AK10: 6 | AL10: 2 | AM10: 4 | AN10: 4 | AO10: 1 | AP10: 12 | AQ10: 2 | AR10: 3 | AS10: 22 | AT10: 2 | AU10: 0 | AV10: 17 | AW10: 2 | AX10: 2 | AY10: 18 | AZ10: 3 | BA10: 1 | BB10: 9 | BC10: 0 | BD10: 0 | BE10: 2 | BF10: 3 | BG10: 1 | BH10: 40 | BI10: 15 | BJ10: 1 | BK10: 1 | BL10: 8 | BM10: 6 | BN10: 9 | BO10: 6 | BP10: 6 | BQ10: 4 | BR10: 1 | BS10: 15 | BT10: 1 | BU10: 6 | BV10: 1 | BW10: 6 | BX10: 8 | BY10: 2 | BZ10: 5 | CA10: 1 | CB10: 6 | CC10: 1 | CD10: 1 | CE10: 4 | CF10: 14 | CG10: 11 | CH10: 3 | CI10: 23 | CJ10: 12 | CK10: 0 | CL10: 10 | CM10: 3 | CN10: 1 | CO10: 1 | CP10: 19 | CQ10: 2 | CR10: 1 | CS10: 2 | CT10: 3 | CU10: 9 | CV10: 1 | CW10: 1 | CX10: 0 | CY10: 0 | CZ10: 20 | DA10: 5 | DB10: 15 | DC10: 5
A11: 02021 | B11: 97*D0 | D11: 01 | E11: 0000 | F11: 6 | H11: 男性_35～39歳 | I11: 345 | J11: 6 | K11: 5 | L11: 1 | M11: 339 | N11: 1 | O11: 0 | P11: 0 | Q11: 0 | R11: 31 | S11: 76 | T11: 7 | U11: 1 | V11: 1 | W11: 1 | X11: 1 | Y11: 2 | Z11: 2 | AA11: 5 | AB11: 0 | AC11: 3 | AD11: 1 | AE11: 0 | AF11: 2 | AG11: 3 | AH11: 2 | AI11: 8 | AJ11: 4 | AK11: 6 | AL11: 3 | AM11: 5 | AN11: 4 | AO11: 1 | AP11: 12 | AQ11: 3 | AR11: 2 | AS11: 25 | AT11: 1 | AU11: 1 | AV11: 19 | AW11: 2 | AX11: 2 | AY11: 22 | AZ11: 3 | BA11: 1 | BB11: 13 | BC11: 0 | BD11: 0 | BE11: 2 | BF11: 2 | BG11: 1 | BH11: 46 | BI11: 20 | BJ11: 1 | BK11: 2 | BL11: 7 | BM11: 7 | BN11: 9 | BO11: 8 | BP11: 6 | BQ11: 4 | BR11: 2 | BS11: 15 | BT11: 1 | BU11: 7 | BV11: 1 | BW11: 6 | BX11: 11 | BY11: 2 | BZ11: 8 | CA11: 1 | CB11: 9 | CC11: 4 | CD11: 2 | CE11: 4 | CF11: 12 | CG11: 9 | CH11: 3 | CI11: 26 | CJ11: 13 | CK11: 1 | CL11: 13 | CM11: 3 | CN11: 2 | CO11: 1 | CP11: 21 | CQ11: 2 | CR11: 2 | CS11: 2 | CT11: 3 | CU11: 11 | CV11: 0 | CW11: 1 | CX11: 0 | CY11: 0 | CZ11: 19 | DA11: 6 | DB11: 13 | DC11: 4
A12: 02021 | B12: 97*D0 | D12: 01 | E12: 0000 | F12: 7 | H12: 男性_40～44歳 | I12: 380 | J12: 6 | K12: 6 | L12: 0 | M12: 374 | N12: 1 | O12: 0 | P12: 0 | Q12: 0 | R12: 39 | S12: 84 | T12: 7 | U12: 1 | V12: 1 | W12: 1 | X12: 1 | Y12: 2 | Z12: 3 | AA12: 5 | AB12: 0 | AC12: 4 | AD12: 2 | AE12: 0 | AF12: 3 | AG12: 2 | AH12: 2 | AI12: 8 | AJ12: 3 | AK12: 6 | AL12: 2 | AM12: 5 | AN12: 5 | AO12: 2 | AP12: 14 | AQ12: 3 | AR12: 3 | AS12: 25 | AT12: 2 | AU12: 1 | AV12: 18 | AW12: 2 | AX12: 3 | AY12: 29 | AZ12: 3 | BA12: 2 | BB12: 18 | BC12: 0 | BD12: 0 | BE12: 2 | BF12: 2 | BG12: 1 | BH12: 51 | BI12: 22 | BJ12: 1 | BK12: 1 | BL12: 8 | BM12: 8 | BN12: 10 | BO12: 7 | BP12: 8 | BQ12: 6 | BR12: 2 | BS12: 16 | BT12: 1 | BU12: 7 | BV12: 1 | BW12: 6 | BX12: 11 | BY12: 2 | BZ12: 8 | CA12: 1 | CB12: 9 | CC12: 4 | CD12: 1 | CE12: 4 | CF12: 13 | CG12: 9 | CH12: 4 | CI12: 25 | CJ12: 12 | CK12: 0 | CL12: 13 | CM12: 4 | CN12: 2 | CO12: 2 | CP12: 24 | CQ12: 3 | CR12: 2 | CS12: 2 | CT12: 2 | CU12: 12 | CV12: 1 | CW12: 1 | CX12: 0 | CY12: 0 | CZ12: 21 | DA12: 7 | DB12: 14 | DC12: 5
A13: 02021 | B13: 97*D0 | D13: 01 | E13: 0000 | F13: 8 | H13: 男性_45～49歳 | I13: 452 | J13: 7 | K13: 6 | L13: 1 | M13: 445 | N13: 1 | O13: 1 | P13: 0 | Q13: 0 | R13: 55 | S13: 101 | T13: 9 | U13: 2 | V13: 2 | W13: 1 | X13: 1 | Y13: 2 | Z13: 4 | AA13: 7 | AB13: 0 | AC13: 4 | AD13: 2 | AE13: 0 | AF13: 4 | AG13: 3 | AH13: 2 | AI13: 10 | AJ13: 4 | AK13: 8 | AL13: 4 | AM13: 7 | AN13: 6 | AO13: 2 | AP13: 15 | AQ13: 2 | AR13: 5 | AS13: 26 | AT13: 3 | AU13: 1 | AV13: 18 | AW13: 2 | AX13: 2 | AY13: 40 | AZ13: 3 | BA13: 3 | BB13: 26 | BC13: 0 | BD13: 0 | BE13: 2 | BF13: 3 | BG13: 2 | BH13: 60 | BI13: 30 | BJ13: 1 | BK13: 1 | BL13: 8 | BM13: 9 | BN13: 11 | BO13: 9 | BP13: 8 | BQ13: 6 | BR13: 2 | BS13: 18 | BT13: 1 | BU13: 7 | BV13: 1 | BW13: 8 | BX13: 14 | BY13: 3 | BZ13: 10 | CA13: 1 | CB13: 9 | CC13: 3 | CD13: 2 | CE13: 3 | CF13: 14 | CG13: 11 | CH13: 3 | CI13: 25 | CJ13: 12 | CK13: 0 | CL13: 12 | CM13: 4 | CN13: 3 | CO13: 2 | CP13: 29 | CQ13: 4 | CR13: 4 | CS13: 3 | CT13: 2 | CU13: 14 | CV13: 1 | CW13: 1 | CX13: 0 | CY13: 0 | CZ13: 21 | DA13: 7 | DB13: 14 | DC13: 7
A14: 02021 | B14: 97*D0 | D14: 01 | E14: 0000 | F14: 9 | H14: 男性_50～54歳 | I14: 438 | J14: 7 | K14: 7 | L14: 1 | M14: 431 | N14: 1 | O14: 1 | P14: 0 | Q14: 0 | R14: 53 | S14: 98 | T14: 8 | U14: 1 | V14: 1 | W14: 1 | X14: 1 | Y14: 3 | Z14: 4 | AA14: 6 | AB14: 0 | AC14: 5 | AD14: 2 | AE14: 0 | AF14: 4 | AG14: 3 | AH14: 2 | AI14: 9 | AJ14: 4 | AK14: 7 | AL14: 3 | AM14: 7 | AN14: 7 | AO14: 3 | AP14: 13 | AQ14: 4 | AR14: 4 | AS14: 23 | AT14: 2 | AU14: 1 | AV14: 17 | AW14: 1 | AX14: 3 | AY14: 41 | AZ14: 2 | BA14: 5 | BB14: 27 | BC14: 0 | BD14: 1 | BE14: 2 | BF14: 2 | BG14: 1 | BH14: 57 | BI14: 30 | BJ14: 1 | BK14: 1 | BL14: 7 | BM14: 8 | BN14: 10 | BO14: 10 | BP14: 8 | BQ14: 6 | BR14: 2 | BS14: 18 | BT14: 2 | BU14: 7 | BV14: 1 | BW14: 9 | BX14: 12 | BY14: 3 | BZ14: 8 | CA14: 1 | CB14: 8 | CC14: 3 | CD14: 2 | CE14: 3 | CF14: 13 | CG14: 10 | CH14: 3 | CI14: 21 | CJ14: 11 | CK14: 0 | CL14: 9 | CM14: 5 | CN14: 3 | CO14: 2 | CP14: 29 | CQ14: 4 | CR14: 3 | CS14: 3 | CT14: 1 | CU14: 15 | CV14: 1 | CW14: 1 | CX14: 0 | CY14: 0 | CZ14: 23 | DA14: 7 | DB14: 15 | DC14: 7
A15: 02021 | B15: 97*D0 | D15: 01 | E15: 0000 | F15: 10 | H15: 男性_55～59歳 | I15: 365 | J15: 7 | K15: 6 | L15: 0 | M15: 359 | N15: 1 | O15: 1 | P15: 0 | Q15: 0 | R15: 40 | S15: 80 | T15: 6 | U15: 1 | V15: 2 | W15: 1 | X15: 1 | Y15: 2 | Z15: 3 | AA15: 6 | AB15: 0 | AC15: 4 | AD15: 1 | AE15: 0 | AF15: 3 | AG15: 2 | AH15: 1 | AI15: 7 | AJ15: 3 | AK15: 6 | AL15: 3 | AM15: 6 | AN15: 6 | AO15: 3 | AP15: 11 | AQ15: 3 | AR15: 3 | AS15: 18 | AT15: 2 | AU15: 1 | AV15: 13 | AW15: 0 | AX15: 3 | AY15: 34 | AZ15: 2 | BA15: 6 | BB15: 21 | BC15: 1 | BD15: 0 | BE15: 1 | BF15: 2 | BG15: 1 | BH15: 48 | BI15: 25 | BJ15: 1 | BK15: 1 | BL15: 7 | BM15: 6 | BN15: 8 | BO15: 10 | BP15: 8 | BQ15: 6 | BR15: 2 | BS15: 16 | BT15: 2 | BU15: 5 | BV15: 1 | BW15: 8 | BX15: 9 | BY15: 2 | BZ15: 5 | CA15: 1 | CB15: 6 | CC15: 3 | CD15: 2 | CE15: 2 | CF15: 16 | CG15: 13 | CH15: 3 | CI15: 18 | CJ15: 10 | CK15: 1 | CL15: 7 | CM15: 4 | CN15: 2 | CO15: 2 | CP15: 24 | CQ15: 3 | CR15: 2 | CS15: 2 | CT15: 1 | CU15: 13 | CV15: 1 | CW15: 1 | CX15: 0 | CY15: 0 | CZ15: 18 | DA15: 4 | DB15: 13 | DC15: 5
A16: 02021 | B16: 97*D0 | D16: 01 | E16: 0000 | F16: 11 | H16: 男性_60～64歳 | I16: 308 | J16: 11 | K16: 10 | L16: 1 | M16: 297 | N16: 1 | O16: 1 | P16: 0 | Q16: 0 | R16: 36 | S16: 55 | T16: 5 | U16: 1 | V16: 1 | W16: 1 | X16: 1 | Y16: 1 | Z16: 2 | AA16: 4 | AB16: 0 | AC16: 2 | AD16: 1 | AE16: 0 | AF16: 2 | AG16: 2 | AH16: 1 | AI16: 6 | AJ16: 2 | AK16: 5 | AL16: 2 | AM16: 3 | AN16: 4 | AO16: 1 | AP16: 7 | AQ16: 2 | AR16: 2 | AS16: 10 | AT16: 1 | AU16: 1 | AV16: 7 | AW16: 0 | AX16: 2 | AY16: 28 | AZ16: 2 | BA16: 6 | BB16: 15 | BC16: 0 | BD16: 0 | BE16: 1 | BF16: 3 | BG16: 1 | BH16: 40 | BI16: 20 | BJ16: 1 | BK16: 1 | BL16: 7 | BM16: 4 | BN16: 8 | BO16: 7 | BP16: 8 | BQ16: 7 | BR16: 1 | BS16: 15 | BT16: 1 | BU16: 5 | BV16: 1 | BW16: 8 | BX16: 8 | BY16: 2 | BZ16: 5 | CA16: 1 | CB16: 6 | CC16: 2 | CD16: 1 | CE16: 3 | CF16: 15 | CG16: 12 | CH16: 4 | CI16: 19 | CJ16: 10 | CK16: 1 | CL16: 8 | CM16: 3 | CN16: 2 | CO16: 1 | CP16: 28 | CQ16: 3 | CR16: 2 | CS16: 2 | CT16: 1 | CU16: 16 | CV16: 3 | CW16: 1 | CX16: 0 | CY16: 0 | CZ16: 11 | DA16: 2 | DB16: 9 | DC16: 4
A17: 02021 | B17: 97*D0 | D17: 01 | E17: 0000 | F17: 12 | H17: 男性_65歳以上 | I17: 538 | J17: 62 | K17: 61 | L17: 1 | M17: 476 | N17: 4 | O17: 3 | P17: 1 | Q17: 0 | R17: 68 | S17: 59 | T17: 7 | U17: 1 | V17: 3 | W17: 1 | X17: 2 | Y17: 1 | Z17: 3 | AA17: 2 | AB17: 0 | AC17: 3 | AD17: 1 | AE17: 0 | AF17: 3 | AG17: 2 | AH17: 1 | AI17: 10 | AJ17: 2 | AK17: 5 | AL17: 1 | AM17: 1 | AN17: 3 | AO17: 0 | AP17: 4 | AQ17: 3 | AR17: 1 | AS17: 5 | AT17: 0 | AU17: 0 | AV17: 3 | AW17: 0 | AX17: 2 | AY17: 35 | AZ17: 1 | BA17: 13 | BB17: 16 | BC17: 1 | BD17: 0 | BE17: 1 | BF17: 2 | BG17: 0 | BH17: 64 | BI17: 22 | BJ17: 1 | BK17: 2 | BL17: 15 | BM17: 7 | BN17: 17 | BO17: 4 | BP17: 25 | BQ17: 23 | BR17: 2 | BS17: 28 | BT17: 1 | BU17: 12 | BV17: 1 | BW17: 14 | BX17: 21 | BY17: 4 | BZ17: 14 | CA17: 3 | CB17: 19 | CC17: 7 | CD17: 5 | CE17: 7 | CF17: 18 | CG17: 11 | CH17: 7 | CI17: 36 | CJ17: 16 | CK17: 1 | CL17: 19 | CM17: 1 | CN17: 0 | CO17: 1 | CP17: 68 | CQ17: 4 | CR17: 5 | CS17: 3 | CT17: 2 | CU17: 46 | CV17: 4 | CW17: 4 | CX17: 1 | CY17: 0 | CZ17: 8 | DA17: 1 | DB17: 7 | DC17: 11

Sheet 女性
I1: 1 | J1: 2 | K1: 3 | L1: 4 | M1: 5 | N1: 6 | O1: 7 | P1: 8 | Q1: 9 | R1: 10 | S1: 11 | T1: 12 | U1: 13 | V1: 14 | W1: 15 | X1: 16 | Y1: 17 | Z1: 18 | AA1: 19 | AB1: 20 | AC1: 21 | AD1: 22 | AE1: 23 | AF1: 24 | AG1: 25 | AH1: 26 | AI1: 27 | AJ1: 28 | AK1: 29 | AL1: 30 | AM1: 31 | AN1: 32 | AO1: 33 | AP1: 34 | AQ1: 35 | AR1: 36 | AS1: 37 | AT1: 38 | AU1: 39 | AV1: 40 | AW1: 41 | AX1: 42 | AY1: 43 | AZ1: 44 | BA1: 45 | BB1: 46 | BC1: 47 | BD1: 48 | BE1: 49 | BF1: 50 | BG1: 51 | BH1: 52 | BI1: 53 | BJ1: 54 | BK1: 55 | BL1: 56 | BM1: 57 | BN1: 58 | BO1: 59 | BP1: 60 | BQ1: 61 | BR1: 62 | BS1: 63 | BT1: 64 | BU1: 65 | BV1: 66 | BW1: 67 | BX1: 68 | BY1: 69 | BZ1: 70 | CA1: 71 | CB1: 72 | CC1: 73 | CD1: 74 | CE1: 75 | CF1: 76 | CG1: 77 | CH1: 78 | CI1: 79 | CJ1: 80 | CK1: 81 | CL1: 82 | CM1: 83 | CN1: 84 | CO1: 85 | CP1: 86 | CQ1: 87 | CR1: 88 | CS1: 89 | CT1: 90 | CU1: 91 | CV1: 92 | CW1: 93 | CX1: 94 | CY1: 95 | CZ1: 96 | DA1: 97 | DB1: 98 | DC1: 99
I2: 1 | J2: 2 | K2: 3 | L2: 4 | M2: 5 | N2: 6 | O2: 7 | P2: 8 | Q2: 9 | R2: 10 | S2: 11 | T2: 12 | U2: 13 | V2: 14 | W2: 15 | X2: 16 | Y2: 17 | Z2: 18 | AA2: 19 | AB2: 20 | AC2: 21 | AD2: 22 | AE2: 23 | AF2: 24 | AG2: 25 | AH2: 26 | AI2: 27 | AJ2: 28 | AK2: 29 | AL2: 30 | AM2: 31 | AN2: 32 | AO2: 33 | AP2: 34 | AQ2: 35 | AR2: 36 | AS2: 37 | AT2: 38 | AU2: 39 | AV2: 40 | AW2: 41 | AX2: 42 | AY2: 43 | AZ2: 44 | BA2: 45 | BB2: 46 | BC2: 47 | BD2: 48 | BE2: 49 | BF2: 50 | BG2: 51 | BH2: 52 | BI2: 53 | BJ2: 54 | BK2: 55 | BL2: 56 | BM2: 57 | BN2: 58 | BO2: 59 | BP2: 60 | BQ2: 61 | BR2: 62 | BS2: 63 | BT2: 64 | BU2: 65 | BV2: 66 | BW2: 67 | BX2: 68 | BY2: 69 | BZ2: 70 | CA2: 71 | CB2: 72 | CC2: 73 | CD2: 74 | CE2: 75 | CF2: 76 | CG2: 77 | CH2: 78 | CI2: 79 | CJ2: 80 | CK2: 81 | CL2: 82 | CM2: 83 | CN2: 84 | CO2: 85 | CP2: 86 | CQ2: 87 | CR2: 88 | CS2: 89 | CT2: 90 | CU2: 91 | CV2: 92 | CW2: 93 | CX2: 94 | CY2: 95 | CZ2: 96 | DA2: 97 | DB2: 98 | DC2: 99
H4: 項目 | I4: 全体 | J4: 農業，林業 | K4: 農業 | L4: 林業 | M4: 非農林業 | N4: 漁業 | O4: 漁業(水産養殖業を除く) | P4: 水産養殖業 | Q4: 鉱業，採石業，砂利採取業 | R4: 建設業 | S4: 製造業 | T4: 食料品製造業 | U4: 飲料・たばこ・飼料製造業 | V4: 繊維工業 | W4: 木材・木製品製造業(家具を除く) | X4: 家具・装備品製造業 | Y4: パルプ・紙・紙加工品製造業 | Z4: 印刷・同関連業 | AA4: 化学工業 | AB4: 石油製品・石炭製品製造業 | AC4: プラスチック製品製造業(別掲を除く) | AD4: ゴム製品製造業 | AE4: なめし革・同製品・毛皮製造業 | AF4: 窯業・土石製品製造業 | AG4: 鉄鋼業 | AH4: 非鉄金属製造業 | AI4: 金属製品製造業 | AJ4: はん用機械器具製造業 | AK4: 生産用機械器具製造業 | AL4: 業務用機械器具製造業 | AM4: 電子部品・デバイス・電子回路製造業 | AN4: 電気機械器具製造業 | AO4: 情報通信機械器具製造業 | AP4: 輸送用機械器具製造業 | AQ4: その他の製造業 | AR4: 電気・ガス・熱供給・水道業 | AS4: 情報通信業 | AT4: 通信業 | AU4: 放送業 | AV4: 情報サービス業 | AW4: インターネット附随サービス業 | AX4: 映像・音声・文字情報制作業 | AY4: 運輸業，郵便業 | AZ4: 鉄道業 | BA4: 道路旅客運送業 | BB4: 道路貨物運送業 | BC4: 水運業 | BD4: 航空運輸業 | BE4: 倉庫業 | BF4: 運輸に附帯するサービス業 | BG4: 郵便業(信書便事業を含む) | BH4: 卸売業，小売業 | BI4: 卸売業 | BJ4: 各種商品小売業 | BK4: 織物・衣服・身の回り品小売業 | BL4: 飲食料品小売業 | BM4: 機械器具小売業 | BN4: その他の小売業 | BO4: 金融業，保険業 | BP4: 不動産業，物品賃貸業 | BQ4: 不動産業 | BR4: 物品賃貸業 | BS4: 学術研究，専門・技術サービス業 | BT4: 学術・開発研究機関 | BU4: 専門サービス業(他に分類されないもの) | BV4: 広告業 | BW4: 技術サービス業(他に分類されないもの) | BX4: 宿泊業，飲食サービス業 | BY4: 宿泊業 | BZ4: 飲食店 | CA4: 持ち帰り・配達飲食サービス業 | CB4: 生活関連サービス業，娯楽業 | CC4: 洗濯・理容・美容・浴場業 | CD4: その他の生活関連サービス業 | CE4: 娯楽業 | CF4: 教育，学習支援業 | CG4: 学校教育 | CH4: その他の教育，学習支援業 | CI4: 医療，福祉 | CJ4: 医療業 | CK4: 保健衛生 | CL4: 社会保険・社会福祉・介護事業 | CM4: 複合サービス事業 | CN4: 郵便局 | CO4: 協同組合(他に分類されないもの) | CP4: サービス業(他に分類されないもの) | CQ4: 廃棄物処理業 | CR4: 自動車整備業 | CS4: 機械等修理業(別掲を除く) | CT4: 職業紹介・労働者派遣業 | CU4: その他の事業サービス業 | CV4: 政治・経済・文化団体 | CW4: 宗教 | CX4: その他のサービス業 | CY4: 外国公務 | CZ4: 公務(他に分類されるものを除く) | DA4: 国家公務 | DB4: 地方公務 | DC4: 分類不能の産業
A5: 02021 | B5: 97*D0 | D5: 01 | E5: 0000 | F5: 1 | H5: 女性 | I5: 3024 | J5: 74 | K5: 73 | L5: 1 | M5: 2950 | N5: 2 | O5: 1 | P5: 1 | Q5: 0 | R5: 85 | S5: 312 | T5: 68 | U5: 4 | V5: 21 | W5: 3 | X5: 3 | Y5: 7 | Z5: 13 | AA5: 20 | AB5: 0 | AC5: 17 | AD5: 4 | AE5: 2 | AF5: 7 | AG5: 3 | AH5: 4 | AI5: 22 | AJ5: 7 | AK5: 12 | AL5: 11 | AM5: 19 | AN5: 18 | AO5: 5 | AP5: 23 | AQ5: 17 | AR5: 6 | AS5: 77 | AT5: 6 | AU5: 3 | AV5: 46 | AW5: 8 | AX5: 15 | AY5: 77 | AZ5: 3 | BA5: 4 | BB5: 41 | BC5: 1 | BD5: 3 | BE5: 12 | BF5: 11 | BG5: 3 | BH5: 547 | BI5: 106 | BJ5: 26 | BK5: 44 | BL5: 188 | BM5: 27 | BN5: 156 | BO5: 87 | BP5: 58 | BQ5: 47 | BR5: 10 | BS5: 96 | BT5: 7 | BU5: 53 | BV5: 7 | BW5: 29 | BX5: 236 | BY5: 30 | BZ5: 162 | CA5: 44 | CB5: 136 | CC5: 76 | CD5: 26 | CE5: 34 | CF5: 204 | CG5: 140 | CH5: 64 | CI5: 680 | CJ5: 317 | CK5: 11 | CL5: 352 | CM5: 21 | CN5: 11 | CO5: 9 | CP5: 190 | CQ5: 6 | CR5: 6 | CS5: 4 | CT5: 17 | CU5: 133 | CV5: 14 | CW5: 8 | CX5: 2 | CY5: 1 | CZ5: 81 | DA5: 17 | DB5: 64 | DC5: 55
A6: 02021 | B6: 97*D0 | D6: 01 | E6: 0000 | F6: 13 | H6: 女性_15～64歳 | I6: 2649 | J6: 35 | K6: 34 | L6: 1 | M6: 2614 | N6: 1 | O6: 1 | P6: 1 | Q6: 0 | R6: 72 | S6: 282 | T6: 59 | U6: 4 | V6: 17 | W6: 3 | X6: 2 | Y6: 6 | Z6: 11 | AA6: 20 | AB6: 0 | AC6: 16 | AD6: 4 | AE6: 2 | AF6: 6 | AG6: 3 | AH6: 3 | AI6: 19 | AJ6: 6 | AK6: 11 | AL6: 11 | AM6: 19 | AN6: 17 | AO6: 5 | AP6: 22 | AQ6: 16 | AR6: 6 | AS6: 76 | AT6: 6 | AU6: 3 | AV6: 45 | AW6: 8 | AX6: 14 | AY6: 71 | AZ6: 3 | BA6: 4 | BB6: 37 | BC6: 1 | BD6: 3 | BE6: 11 | BF6: 10 | BG6: 3 | BH6: 485 | BI6: 96 | BJ6: 23 | BK6: 40 | BL6: 161 | BM6: 24 | BN6: 141 | BO6: 84 | BP6: 44 | BQ6: 35 | BR6: 10 | BS6: 89 | BT6: 7 | BU6: 49 | BV6: 7 | BW6: 26 | BX6: 198 | BY6: 23 | BZ6: 140 | CA6: 35 | CB6: 112 | CC6: 60 | CD6: 22 | CE6: 31 | CF6: 188 | CG6: 133 | CH6: 54 | CI6: 612 | CJ6: 300 | CK6: 10 | CL6: 301 | CM6: 20 | CN6: 11 | CO6: 9 | CP6: 153 | CQ6: 5 | CR6: 4 | CS6: 4 | CT6: 17 | CU6: 104 | CV6: 12 | CW6: 5 | CX6: 2 | CY6: 1 | CZ6: 77 | DA6: 16 | DB6: 61 | DC6: 45
A7: 02021 | B7: 97*D0 | D7: 01 | E7: 0000 | F7: 2 | H7: 女性_15～19歳 | I7: 55 | J7: 0 | K7: 0 | L7: - | M7: 55 | N7: - | O7: - | P7: - | Q7: - | R7: 0 | S7: 3 | T7: 1 | U7: 0 | V7: 0 | W7: 0 | X7: 0 | Y7: 0 | Z7: 0 | AA7: 0 | AB7: - | AC7: 0 | AD7: 0 | AE7: 0 | AF7: 0 | AG7: 0 | AH7: 0 | AI7: 0 | AJ7: 0 | AK7: 0 | AL7: 0 | AM7: 0 | AN7: 0 | AO7: 0 | AP7: 1 | AQ7: 0 | AR7: 0 | AS7: 0 | AT7: 0 | AU7: 0 | AV7: 0 | AW7: 0 | AX7: - | AY7: 1 | AZ7: 0 | BA7: - | BB7: 0 | BC7: 0 | BD7: - | BE7: - | BF7: 0 | BG7: - | BH7: 17 | BI7: 0 | BJ7: 1 | BK7: 1 | BL7: 11 | BM7: 0 | BN7: 4 | BO7: 0 | BP7: 0 | BQ7: 0 | BR7: 0 | BS7: 0 | BT7: - | BU7: 0 | BV7: - | BW7: 0 | BX7: 23 | BY7: 1 | BZ7: 21 | CA7: 1 | CB7: 2 | CC7: 0 | CD7: 0 | CE7: 1 | CF7: 3 | CG7: 0 | CH7: 2 | CI7: 2 | CJ7: 1 | CK7: 0 | CL7: 1 | CM7: 0 | CN7: 0 | CO7: 0 | CP7: 1 | CQ7: 0 | CR7: - | CS7: 0 | CT7: 0 | CU7: 1 | CV7: 0 | CW7: - | CX7: 0 | CY7: - | CZ7: 0 | DA7: 0 | DB7: 0 | DC7: 1
A8: 02021 | B8: 97*D0 | D8: 01 | E8: 0000 | F8: 3 | H8: 女性_20～24歳 | I8: 219 | J8: 1 | K8: 1 | L8: 0 | M8: 218 | N8: - | O8: - | P8: - | Q8: - | R8: 3 | S8: 20 | T8: 5 | U8: 0 | V8: 1 | W8: 0 | X8: 0 | Y8: 0 | Z8: 1 | AA8: 1 | AB8: 0 | AC8: 1 | AD8: 0 | AE8: - | AF8: 0 | AG8: 0 | AH8: 0 | AI8: 1 | AJ8: 1 | AK8: 1 | AL8: 0 | AM8: 1 | AN8: 1 | AO8: 0 | AP8: 3 | AQ8: 1 | AR8: 0 | AS8: 7 | AT8: 0 | AU8: 0 | AV8: 5 | AW8: 1 | AX8: 1 | AY8: 4 | AZ8: 0 | BA8: 0 | BB8: 2 | BC8: 0 | BD8: 0 | BE8: 0 | BF8: 1 | BG8: 0 | BH8: 44 | BI8: 5 | BJ8: 1 | BK8: 5 | BL8: 17 | BM8: 3 | BN8: 13 | BO8: 5 | BP8: 2 | BQ8: 1 | BR8: 1 | BS8: 5 | BT8: 0 | BU8: 2 | BV8: 1 | BW8: 3 | BX8: 33 | BY8: 3 | BZ8: 27 | CA8: 3 | CB8: 12 | CC8: 6 | CD8: 1 | CE8: 5 | CF8: 17 | CG8: 9 | CH8: 8 | CI8: 43 | CJ8: 25 | CK8: 0 | CL8: 17 | CM8: 1 | CN8: 1 | CO8: 1 | CP8: 9 | CQ8: 0 | CR8: 0 | CS8: 0 | CT8: 1 | CU8: 7 | CV8: 0 | CW8: 0 | CX8: 0 | CY8: 0 | CZ8: 5 | DA8: 2 | DB8: 4 | DC8: 5
A9: 02021 | B9: 97*D0 | D9: 01 | E9: 0000 | F9: 4 | H9: 女性_25～29歳 | I9: 263 | J9: 2 | K9: 2 | L9: 0 | M9: 261 | N9: 0 | O9: - | P9: 0 | Q9: 0 | R9: 6 | S9: 27 | T9: 6 | U9: 1 | V9: 1 | W9: 0 | X9: 0 | Y9: 1 | Z9: 1 | AA9: 2 | AB9: 0 | AC9: 1 | AD9: 0 | AE9: 0 | AF9: 0 | AG9: 1 | AH9: 0 | AI9: 2 | AJ9: 1 | AK9: 1 | AL9: 1 | AM9: 2 | AN9: 2 | AO9: 1 | AP9: 2 | AQ9: 2 | AR9: 1 | AS9: 15 | AT9: 1 | AU9: 0 | AV9: 10 | AW9: 2 | AX9: 2 | AY9: 7 | AZ9: 1 | BA9: 0 | BB9: 3 | BC9: 0 | BD9: 1 | BE9: 1 | BF9: 1 | BG9: 0 | BH9: 44 | BI9: 11 | BJ9: 1 | BK9: 5 | BL9: 9 | BM9: 3 | BN9: 14 | BO9: 11 | BP9: 4 | BQ9: 3 | BR9: 1 | BS9: 11 | BT9: 1 | BU9: 5 | BV9: 1 | BW9: 4 | BX9: 12 | BY9: 3 | BZ9: 7 | CA9: 2 | CB9: 11 | CC9: 5 | CD9: 2 | CE9: 4 | CF9: 18 | CG9: 14 | CH9: 4 | CI9: 63 | CJ9: 36 | CK9: 1 | CL9: 26 | CM9: 1 | CN9: 1 | CO9: 1 | CP9: 15 | CQ9: 0 | CR9: 0 | CS9: 0 | CT9: 4 | CU9: 10 | CV9: 1 | CW9: 0 | CX9: 0 | CY9: - | CZ9: 10 | DA9: 2 | DB9: 7 | DC9: 4
A10: 02021 | B10: 97*D0 | D10: 01 | E10: 0000 | F10: 5 | H10: 女性_30～34歳 | I10: 247 | J10: 2 | K10: 2 | L10: 0 | M10: 245 | N10: 0 | O10: - | P10: 0 | Q10: - | R10: 6 | S10: 26 | T10: 5 | U10: 0 | V10: 2 | W10: 0 | X10: 0 | Y10: 1 | Z10: 1 | AA10: 2 | AB10: 0 | AC10: 1 | AD10: 0 | AE10: 0 | AF10: 0 | AG10: 0 | AH10: 0 | AI10: 1 | AJ10: 1 | AK10: 1 | AL10: 1 | AM10: 1 | AN10: 1 | AO10: 0 | AP10: 3 | AQ10: 2 | AR10: 1 | AS10: 13 | AT10: 1 | AU10: 0 | AV10: 8 | AW10: 2 | AX10: 2 | AY10: 6 | AZ10: 1 | BA10: 0 | BB10: 3 | BC10: 0 | BD10: 1 | BE10: 1 | BF10: 1 | BG10: 0 | BH10: 41 | BI10: 10 | BJ10: 1 | BK10: 4 | BL10: 10 | BM10: 2 | BN10: 13 | BO10: 8 | BP10: 5 | BQ10: 3 | BR10: 1 | BS10: 10 | BT10: 1 | BU10: 6 | BV10: 1 | BW10: 3 | BX10: 13 | BY10: 2 | BZ10: 9 | CA10: 2 | CB10: 11 | CC10: 5 | CD10: 2 | CE10: 4 | CF10: 17 | CG10: 14 | CH10: 3 | CI10: 58 | CJ10: 32 | CK10: 1 | CL10: 25 | CM10: 2 | CN10: 1 | CO10: 1 | CP10: 15 | CQ10: 0 | CR10: 0 | CS10: 0 | CT10: 3 | CU10: 10 | CV10: 1 | CW10: 0 | CX10: 0 | CY10: 0 | CZ10: 8 | DA10: 1 | DB10: 7 | DC10: 4
A11: 02021 | B11: 97*D0 | D11: 01 | E11: 0000 | F11: 6 | H11: 女性_35～39歳 | I11: 274 | J11: 3 | K11: 3 | L11: 0 | M11: 271 | N11: 0 | O11: 0 | P11: 0 | Q11: - | R11: 8 | S11: 29 | T11: 5 | U11: 0 | V11: 2 | W11: 0 | X11: 0 | Y11: 1 | Z11: 1 | AA11: 3 | AB11: - | AC11: 2 | AD11: 1 | AE11: 0 | AF11: 1 | AG11: 0 | AH11: 0 | AI11: 2 | AJ11: 1 | AK11: 1 | AL11: 1 | AM11: 2 | AN11: 2 | AO11: 0 | AP11: 2 | AQ11: 2 | AR11: 0 | AS11: 11 | AT11: 1 | AU11: 1 | AV11: 6 | AW11: 1 | AX11: 2 | AY11: 7 | AZ11: 1 | BA11: 0 | BB11: 3 | BC11: 0 | BD11: 1 | BE11: 1 | BF11: 1 | BG11: 0 | BH11: 47 | BI11: 11 | BJ11: 2 | BK11: 5 | BL11: 13 | BM11: 3 | BN11: 14 | BO11: 9 | BP11: 5 | BQ11: 3 | BR11: 1 | BS11: 12 | BT11: 1 | BU11: 7 | BV11: 1 | BW11: 3 | BX11: 16 | BY11: 2 | BZ11: 11 | CA11: 3 | CB11: 12 | CC11: 7 | CD11: 2 | CE11: 3 | CF11: 18 | CG11: 14 | CH11: 5 | CI11: 67 | CJ11: 34 | CK11: 1 | CL11: 32 | CM11: 2 | CN11: 1 | CO11: 1 | CP11: 15 | CQ11: 0 | CR11: 0 | CS11: 0 | CT11: 2 | CU11: 10 | CV11: 1 | CW11: 0 | CX11: 0 | CY11: 0 | CZ11: 7 | DA11: 1 | DB11: 6 | DC11: 4
A12: 02021 | B12: 97*D0 | D12: 01 | E12: 0000 | F12: 7 | H12: 女性_40～44歳 | I12: 314 | J12: 4 | K12: 4 | L12: 0 | M12: 310 | N12: 0 | O12: 0 | P12: 0 | Q12: - | R12: 9 | S12: 36 | T12: 6 | U12: 1 | V12: 2 | W12: 0 | X12: 0 | Y12: 1 | Z12: 2 | AA12: 3 | AB12: 0 | AC12: 2 | AD12: 1 | AE12: 0 | AF12: 1 | AG12: 0 | AH12: 0 | AI12: 2 | AJ12: 1 | AK12: 1 | AL12: 1 | AM12: 3 | AN12: 2 | AO12: 1 | AP12: 3 | AQ12: 3 | AR12: 1 | AS12: 9 | AT12: 1 | AU12: 0 | AV12: 5 | AW12: 1 | AX12: 1 | AY12: 9 | AZ12: 0 | BA12: 0 | BB12: 5 | BC12: 0 | BD12: 0 | BE12: 1 | BF12: 1 | BG12: 0 | BH12: 54 | BI12: 12 | BJ12: 2 | BK12: 5 | BL12: 15 | BM12: 3 | BN12: 17 | BO12: 9 | BP12: 5 | BQ12: 4 | BR12: 1 | BS12: 12 | BT12: 1 | BU12: 7 | BV12: 1 | BW12: 3 | BX12: 20 | BY12: 2 | BZ12: 14 | CA12: 4 | CB12: 13 | CC12: 8 | CD12: 2 | CE12: 3 | CF12: 21 | CG12: 16 | CH12: 5 | CI12: 77 | CJ12: 40 | CK12: 1 | CL12: 36 | CM12: 2 | CN12: 1 | CO12: 1 | CP12: 18 | CQ12: 1 | CR12: 1 | CS12: 1 | CT12: 2 | CU12: 12 | CV12: 2 | CW12: 1 | CX12: 0 | CY12: 0 | CZ12: 9 | DA12: 1 | DB12: 7 | DC12: 5
